Workbook

Sheet day 1
X1: Day 1 | Z1: Day 1 | AA1: Day 2
B2: Name | C2: 1 | D2: 2 | E2: 3 | F2: 4 | G2: 5 | H2: 6 | I2: 7 | J2: 8 | K2: 9 | L2: Front | M2: 10 | N2: 11 | O2: 12 | P2: 13 | Q2: 14 | R2: 15 | S2: 16 | T2: 17 | U2: 18 | V2: Back | W2: Total | X2: HDCP | Z2: Net | AA2: HDCP
A3: 1 | B3: Colin Sullivan | C3: 6 | D3: 5 | E3: 6 | F3: 9 | G3: 5 | H3: 6 | I3: 6 | J3: 5 | K3: 6 | L3: =SUM(C3:K3) -> 54 | M3: 6 | N3: 7 | O3: 6 | P3: 6 | Q3: 5 | R3: 4 | S3: 6 | T3: 5 | U3: 5 | V3: =SUM(M3:U3) -> 50 | W3: =+L3+V3 -> 104 | X3: 36 | Y3: =(+W3-70)*0.87 -> 29.58 | Z3: =+W3-X3 -> 68 | AA3: =(W3-70)*0.875 -> 29.75
A4: =+A3+1 -> 2 | B4: Bernie Sullivan | C4: 4 | D4: 5 | E4: 4 | F4: 5 | G4: 3 | H4: 4 | I4: 4 | J4: 5 | K4: 4 | L4: =SUM(C4:K4) -> 38 | M4: 6 | N4: 5 | O4: 5 | P4: 7 | Q4: 5 | R4: 5 | S4: 4 | T4: 7 | U4: 4 | V4: =SUM(M4:U4) -> 48 | W4: =+L4+V4 -> 86 | X4: 22.75 | Y4: =(+W4-70)*0.875 -> 14 | Z4: =+W4-X4 -> 63.25 | AA4: =(W4-70)*0.875 -> 14
A5: =+A4+1 -> 3 | B5: Joe McCardel | C5: 6 | D5: 6 | E5: 6 | F5: 7 | G5: 5 | H5: 4 | I5: 5 | J5: 6 | K5: 4 | L5: =SUM(C5:K5) -> 49 | M5: 6 | N5: 5 | O5: 8 | P5: 8 | Q5: 4 | R5: 3 | S5: 9 | T5: 9 | U5: 4 | V5: =SUM(M5:U5) -> 56 | W5: =+L5+V5 -> 105 | X5: 29.75 | Y5: =(+W5-70)*0.875 -> 30.625 | Z5: =+W5-X5 -> 75.25 | AA5: =(W5-70)*0.875 -> 30.625
A6: =+A5+1 -> 4 | B6: Dave Brauer | C6: 5 | D6: 5 | E6: 5 | F6: 5 | G6: 4 | H6: 4 | I6: 6 | J6: 5 | K6: 5 | L6: =SUM(C6:K6) -> 44 | M6: 5 | N6: 5 | O6: 4 | P6: 7 | Q6: 4 | R6: 4 | S6: 5 | T6: 5 | U6: 5 | V6: =SUM(M6:U6) -> 44 | W6: =+L6+V6 -> 88 | X6: 20.125 | Y6: =(+W6-70)*0.875 -> 15.75 | Z6: =+W6-X6 -> 67.875 | AA6: =(W6-70)*0.875 -> 15.75
A7: =+A6+1 -> 5 | B7: John Sullivan | C7: 6 | D7: 5 | E7: 5 | F7: 5 | G7: 4 | H7: 4 | I7: 6 | J7: 5 | K7: 5 | L7: =SUM(C7:K7) -> 45 | M7: 6 | N7: 5 | O7: 7 | P7: 7 | Q7: 3 | R7: 4 | S7: 6 | T7: 6 | U7: 6 | V7: =SUM(M7:U7) -> 50 | W7: =+L7+V7 -> 95 | X7: 18.375 | Y7: =(+W7-70)*0.875 -> 21.875 | Z7: =+W7-X7 -> 76.625 | AA7: =(W7-70)*0.875 -> 21.875
A8: =+A7+1 -> 6 | B8: Ralph | C8: 4 | D8: 4 | E8: 4 | F8: 5 | G8: 4 | H8: 4 | I8: 5 | J8: 5 | K8: 5 | L8: =SUM(C8:K8) -> 40 | M8: 4 | N8: 5 | O8: 5 | P8: 6 | Q8: 4 | R8: 3 | S8: 6 | T8: 5 | U8: 5 | V8: =SUM(M8:U8) -> 43 | W8: =+L8+V8 -> 83 | X8: 24.5 | Y8: =(+W8-70)*0.875 -> 11.375 | Z8: =+W8-X8 -> 58.5 | AA8: =(W8-70)*0.875 -> 11.375
A9: =+A8+1 -> 7 | B9: Leo | C9: 11 | D9: 7 | E9: 9 | F9: 9 | G9: 4 | H9: 5 | I9: 10 | J9: 9 | K9: 6 | L9: =SUM(C9:K9) -> 70 | M9: 7 | N9: 7 | O9: 8 | P9: 9 | Q9: 4 | R9: 7 | S9: 8 | T9: 7 | U9: 8 | V9: =SUM(M9:U9) -> 65 | W9: =+L9+V9 -> 135 | X9: 56.875 | Y9: =(+W9-70)*0.875 -> 56.875 | Z9: =+W9-X9 -> 78.125 | AA9: =(W9-70)*0.875 -> 56.875
A10: =+A9+1 -> 8 | B10: Matt Lawrence | C10: 5 | D10: 4 | E10: 5 | F10: 8 | G10: 3 | H10: 4 | I10: 4 | J10: 5 | K10: 5 | L10: =SUM(C10:K10) -> 43 | M10: 5 | N10: 6 | O10: 5 | P10: 6 | Q10: 4 | R10: 4 | S10: 5 | T10: 8 | U10: 5 | V10: =SUM(M10:U10) -> 48 | W10: =+L10+V10 -> 91 | X10: 14.875 | Y10: =(+W10-70)*0.875 -> 18.375 | Z10: =+W10-X10 -> 76.125 | AA10: =(W10-70)*0.875 -> 18.375
A11: =+A10+1 -> 9 | B11: Jerry Flynn | C11: 5 | D11: 5 | E11: 4 | F11: 6 | G11: 4 | H11: 4 | I11: 6 | J11: 5 | K11: 5 | L11: =SUM(C11:K11) -> 44 | M11: 5 | N11: 7 | O11: 5 | P11: 6 | Q11: 3 | R11: 3 | S11: 6 | T11: 6 | U11: 4 | V11: =SUM(M11:U11) -> 45 | W11: =+L11+V11 -> 89 | X11: 15.75 | Y11: =(+W11-70)*0.875 -> 16.625 | Z11: =+W11-X11 -> 73.25 | AA11: =(W11-70)*0.875 -> 16.625
A12: =+A11+1 -> 10 | B12: Mike Flynn | C12: 5 | D12: 4 | E12: 4 | F12: 5 | G12: 4 | H12: 4 | I12: 4 | J12: 4 | K12: 4 | L12: =SUM(C12:K12) -> 38 | M12: 5 | N12: 5 | O12: 6 | P12: 5 | Q12: 3 | R12: 3 | S12: 5 | T12: 5 | U12: 3 | V12: =SUM(M12:U12) -> 40 | W12: =+L12+V12 -> 78 | X12: 13.125 | Y12: =(+W12-70)*0.875 -> 7 | Z12: =+W12-X12 -> 64.875 | AA12: =(W12-70)*0.875 -> 7
A13: =+A12+1 -> 11 | B13: Sean Flynn | C13: 5 | D13: 4 | E13: 3 | F13: 7 | G13: 4 | H13: 3 | I13: 7 | J13: 5 | K13: 4 | L13: =SUM(C13:K13) -> 42 | M13: 4 | N13: 3 | O13: 6 | P13: 6 | Q13: 5 | R13: 4 | S13: 6 | T13: 5 | U13: 4 | V13: =SUM(M13:U13) -> 43 | W13: =+L13+V13 -> 85 | X13: 5 | Z13: =+W13-X13 -> 80 | AA13: =(W13-70)*0.875 -> 13.125
A14: =+A13+1 -> 12 | B14: Kevin Fitzgerald | C14: 6 | D14: 6 | E14: 5 | F14: 7 | G14: 3 | H14: 4 | I14: 5 | J14: 5 | K14: 5 | L14: =SUM(C14:K14) -> 46 | M14: 6 | N14: 6 | O14: 5 | P14: 6 | Q14: 3 | R14: 8 | S14: 5 | T14: 6 | U14: 8 | V14: =SUM(M14:U14) -> 53 | W14: =+L14+V14 -> 99 | X14: 25.375 | Y14: =(+W14-70)*0.875 -> 25.375 | Z14: =+W14-X14 -> 73.625 | AA14: =(W14-70)*0.875 -> 25.375
A15: =+A14+1 -> 13 | B15: Richard McGovern | C15: 5 | D15: 5 | E15: 6 | F15: 6 | G15: 5 | H15: 4 | I15: 6 | J15: 7 | K15: 5 | L15: =SUM(C15:K15) -> 49 | M15: 7 | N15: 5 | O15: 7 | P15: 7 | Q15: 3 | R15: 4 | S15: 6 | T15: 5 | U15: 5 | V15: =SUM(M15:U15) -> 49 | W15: =+L15+V15 -> 98 | X15: 28 | Y15: =(+W15-70)*0.875 -> 24.5 | Z15: =+W15-X15 -> 70 | AA15: =(W15-70)*0.875 -> 24.5
A16: =+A15+1 -> 14 | B16: Mike Fitzgerald | C16: 4 | D16: 5 | E16: 4 | F16: 5 | G16: 3 | H16: 2 | I16: 5 | J16: 6 | K16: 5 | L16: =SUM(C16:K16) -> 39 | M16: 9 | N16: 4 | O16: 5 | P16: 6 | Q16: 4 | R16: 3 | S16: 4 | T16: 5 | U16: 4 | V16: =SUM(M16:U16) -> 44 | W16: =+L16+V16 -> 83 | X16: 14 | Y16: =(+W16-70)*0.875 -> 11.375 | Z16: =+W16-X16 -> 69 | AA16: =(W16-70)*0.875 -> 11.375
A17: =+A16+1 -> 15 | B17: Matt Brauer | C17: 4 | D17: 5 | E17: 4 | F17: 5 | G17: 3 | H17: 4 | I17: 4 | J17: 4 | K17: 5 | L17: =SUM(C17:K17) -> 38 | M17: 4 | N17: 6 | O17: 4 | P17: 5 | Q17: 4 | R17: 3 | S17: 5 | T17: 4 | U17: 4 | V17: =SUM(M17:U17) -> 39 | W17: =+L17+V17 -> 77 | X17: 0 | Y17: =(+W17-70)*0.875 -> 6.125 | Z17: =+W17-X17 -> 77 | AA17: =(W17-70)*0.875 -> 6.125
A18: =+A17+1 -> 16 | B18: Blake Dougan | C18: 5 | D18: 5 | E18: 5 | F18: 6 | G18: 6 | H18: 6 | I18: 6 | J18: 6 | K18: 6 | L18: =SUM(C18:K18) -> 51 | M18: 7 | N18: 6 | O18: 6 | P18: 7 | Q18: 3 | R18: 5 | S18: 5 | T18: 5 | U18: 7 | V18: =SUM(M18:U18) -> 51 | W18: =+L18+V18 -> 102 | X18: 0 | Z18: =+W18-X18 -> 102 | AA18: =(W18-70)*0.875 -> 28
A19: =+A18+1 -> 17 | B19: Mike Dougan | C19: 7 | D19: 3 | E19: 6 | F19: 6 | G19: 4 | H19: 4 | I19: 6 | J19: 5 | K19: 6 | L19: =SUM(C19:K19) -> 47 | M19: 6 | N19: 6 | O19: 5 | P19: 6 | Q19: 4 | R19: 4 | S19: 5 | T19: 6 | U19: 8 | V19: =SUM(M19:U19) -> 50 | W19: =+L19+V19 -> 97 | X19: 0 | Z19: =+W19-X19 -> 97 | AA19: =(W19-70)*0.875 -> 23.625
A20: =+A19+1 -> 18 | B20: TJ Williams | C20: 4 | D20: 7 | E20: 6 | F20: 10 | G20: 4 | H20: 7 | I20: 5 | J20: 4 | K20: 6 | L20: =SUM(C20:K20) -> 53 | M20: 6 | N20: 5 | O20: 6 | P20: 6 | Q20: 3 | R20: 6 | S20: 5 | T20: 4 | U20: 5 | V20: =SUM(M20:U20) -> 46 | W20: =+L20+V20 -> 99 | X20: 0 | Z20: =+W20-X20 -> 99 | AA20: =(W20-70)*0.875 -> 25.375
A21: =+A20+1 -> 19 | B21: Brian McGovern | C21: 5 | D21: 5 | E21: 5 | F21: 5 | G21: 3 | H21: 4 | I21: 6 | J21: 6 | K21: 5 | L21: =SUM(C21:K21) -> 44 | M21: 5 | N21: 4 | O21: 4 | P21: 7 | Q21: 4 | R21: 5 | S21: 5 | T21: 5 | U21: 5 | V21: =SUM(M21:U21) -> 44 | W21: =+L21+V21 -> 88 | X21: 15 | Z21: =+W21-X21 -> 73 | AA21: =(W21-70)*0.875 -> 15.75
A22: =+A21+1 -> 20 | B22: Dave Keyser | C22: 5 | D22: 5 | E22: 5 | F22: 9 | G22: 4 | H22: 5 | I22: 7 | J22: 6 | K22: 5 | L22: =SUM(C22:K22) -> 51 | M22: 6 | N22: 6 | O22: 5 | P22: 7 | Q22: 4 | R22: 4 | S22: 7 | T22: 7 | U22: 5 | V22: =SUM(M22:U22) -> 51 | W22: =+L22+V22 -> 102 | X22: 24 | Y22: =SUM(M22:U22) -> 51 | Z22: =+W22-X22 -> 78 | AA22: =(W22-70)*0.875 -> 28
A23: =+A22+1 -> 21 | B23: Jack Sullivan | C23: 7 | D23: 4 | E23: 6 | F23: 7 | G23: 5 | H23: 4 | I23: 9 | J23: 5 | K23: 7 | L23: =SUM(C23:K23) -> 54 | M23: 6 | N23: 6 | O23: 7 | P23: 9 | Q23: 3 | R23: 5 | S23: 6 | T23: 8 | U23: 5 | V23: =SUM(M23:U23) -> 55 | W23: =+L23+V23 -> 109 | X23: 31 | Y23: =(+W23-70)*0.875 -> 34.125 | Z23: =+W23-X23 -> 78 | AA23: =(W23-70)*0.875 -> 34.125
A24: =+A23+1 -> 22 | B24: Chris Flynn | C24: 5 | D24: 7 | E24: 5 | F24: 7 | G24: 4 | H24: 4 | I24: 5 | J24: 7 | K24: 4 | L24: =SUM(C24:K24) -> 48 | M24: 5 | N24: 5 | O24: 6 | P24: 8 | Q24: 3 | R24: 7 | S24: 4 | T24: 5 | U24: 4 | V24: =SUM(M24:U24) -> 47 | W24: =+L24+V24 -> 95 | X24: 24 | Y24: =(+W24-70)*0.875 -> 21.875 | Z24: =+W24-X24 -> 71 | AA24: =(W24-70)*0.875 -> 21.875
B25: HDCP | C25: 11 | D25: 17 | E25: 15 | F25: 7 | G25: 3 | H25: 9 | I25: 1 | J25: 13 | K25: 5 | M25: 12 | N25: 18 | O25: 16 | P25: 8 | Q25: 4 | R25: 10 | S25: 2 | T25: 14 | U25: 6
B27: Net of HDCP
A28: 1 | B28: =+B3 -> Colin Sullivan | C28: =+C3-2 -> 4 | D28: =+D3-2 -> 3 | E28: =+E3-2 -> 4 | F28: =+F3-2 -> 7 | G28: =+G3-2 -> 3 | H28: =+H3-2 -> 4 | I28: =+I3-2 -> 4 | J28: =+J3-2 -> 3 | K28: =+K3-2 -> 4 | L28: =SUM(C28:K28) -> 36 | M28: =+M3-2 -> 4 | N28: =+N3-2 -> 5 | O28: =+O3-2 -> 4 | P28: =+P3-2 -> 4 | Q28: =+Q3-2 -> 3 | R28: =+R3-2 -> 2 | S28: =+S3-2 -> 4 | T28: =+T3-2 -> 3 | U28: =+U3-2 -> 3 | V28: =SUM(M28:U28) -> 32 | W28: =+V28+L28 -> 68 | X28: =(0.5*6)-(0.5*6) -> 0 | Y28: =(0.5*4)-(0.5*10) -> -3 | Z28: =(1*5)-(1*9) -> -4 | AA28: =SUM(X28:Z28) -> -7 | AB28: -2.6 | AC28: =SUM(AA28:AB28) -> -9.6
A29: =+A28+1 -> 2 | B29: =+B4 -> Bernie Sullivan | C29: =+C4-1 -> 3 | D29: =+D4-1 -> 4 | E29: =+E4-1 -> 3 | F29: =+F4-1 -> 4 | G29: =+G4-2 -> 1 | H29: =+H4-1 -> 3 | I29: =+I4-2 -> 2 | J29: =+J4-1 -> 4 | K29: =+K4-2 -> 2 | L29: =SUM(C29:K29) -> 26 | M29: =+M4-1 -> 5 | N29: =+N4-1 -> 4 | O29: =+O4-1 -> 4 | P29: =+P4-1 -> 6 | Q29: =+Q4-2 -> 3 | R29: =+R4-1 -> 4 | S29: =+S4-2 -> 2 | T29: =+T4-1 -> 6 | U29: =+U4-1 -> 3 | V29: =SUM(M29:U29) -> 37 | W29: =+V29+L29 -> 63 | X29: =(0.5*6)-(0.5*6) -> 0 | Y29: =(0.5*4)-(0.5*10) -> -3 | Z29: =(1*5)-(1*9) -> -4 | AA29: =SUM(X29:Z29) -> -7 | AB29: -4.7 | AC29: =SUM(AA29:AB29) -> -11.7
A30: =+A29+1 -> 3 | B30: =+B5 -> Joe McCardel | C30: =+C5-2 -> 4 | D30: =+D5-1 -> 5 | E30: =+E5-1 -> 5 | F30: =+F5-2 -> 5 | G30: =+G5-2 -> 3 | H30: =+H5-2 -> 2 | I30: =+I5-2 -> 3 | J30: =+J5-1 -> 5 | K30: =+K5-2 -> 2 | L30: =SUM(C30:K30) -> 34 | M30: =+M5-2 -> 4 | N30: =+N5-1 -> 4 | O30: =+O5-1 -> 7 | P30: =+P5-2 -> 6 | Q30: =+Q5-2 -> 2 | R30: =+R5-2 -> 1 | S30: =+S5-2 -> 7 | T30: =+T5-1 -> 8 | U30: =+U5-2 -> 2 | V30: =SUM(M30:U30) -> 41 | W30: =+V30+L30 -> 75 | X30: =(0.5*2)-(0.5*12) -> -5 | Y30: =(0.5*13)-(0.5*1) -> 6 | Z30: =(1*8)-(1*7) -> 1 | AA30: =SUM(X30:Z30) -> 2 | AB30: -0.3 | AC30: =SUM(AA30:AB30) -> 1.7
A31: =+A30+1 -> 4 | B31: =+B6 -> Dave Brauer | C31: =+C6-1 -> 4 | D31: =+D6-1 -> 4 | E31: =+E6-1 -> 4 | F31: =+F6-1 -> 4 | G31: =+G6-1 -> 3 | H31: =+H6-1 -> 3 | I31: =+I6-2 -> 4 | J31: =+J6-1 -> 4 | K31: =+K6-1 -> 4 | L31: =SUM(C31:K31) -> 34 | M31: =+M6-1 -> 4 | N31: =+N6-1 -> 4 | O31: =+O6-1 -> 3 | P31: =+P6-1 -> 6 | Q31: =+Q6-1 -> 3 | R31: =+R6-1 -> 3 | S31: =+S6-2 -> 3 | T31: =+T6-1 -> 4 | U31: =+U6-1 -> 4 | V31: =SUM(M31:U31) -> 34 | W31: =+V31+L31 -> 68 | X31: =(0.5*6)-(0.5*6) -> 0 | Y31: =(0.5*13)-(0.5*1) -> 6 | Z31: =(1*11)-(1*3) -> 8 | AA31: =SUM(X31:Z31) -> 14 | AB31: 4.9 | AC31: =SUM(AA31:AB31) -> 18.9
A32: =+A31+1 -> 5 | B32: =+B7 -> John Sullivan | C32: =+C7-1 -> 5 | D32: =+D7-1 -> 4 | E32: =+E7-1 -> 4 | F32: =+F7-1 -> 4 | G32: =+G7-1 -> 3 | H32: =+H7-1 -> 3 | I32: =+I7-1 -> 5 | J32: =+J7-1 -> 4 | K32: =+K7-1 -> 4 | L32: =SUM(C32:K32) -> 36 | M32: =+M7-1 -> 5 | N32: =+N7-1 -> 4 | O32: =+O7-1 -> 6 | P32: =+P7-1 -> 6 | Q32: =+Q7-1 -> 2 | R32: =+R7-1 -> 3 | S32: =+S7-1 -> 5 | T32: =+T7-1 -> 5 | U32: =+U7-1 -> 5 | V32: =SUM(M32:U32) -> 41 | W32: =+V32+L32 -> 77 | X32: =(0.5*6)-(0.5*6) -> 0 | Y32: =(0.5*12)-(0.5*3) -> 4.5 | Z32: =(1*10)-(1*5) -> 5 | AA32: =SUM(X32:Z32) -> 9.5 | AB32: 4.9 | AC32: =SUM(AA32:AB32) -> 14.4
A33: =+A32+1 -> 6 | B33: =+B8 -> Ralph | C33: =+C8-1 -> 3 | D33: =+D8-1 -> 3 | E33: =+E8-1 -> 3 | F33: =+F8-2 -> 3 | G33: =+G8-2 -> 2 | H33: =+H8-1 -> 3 | I33: =+I8-2 -> 3 | J33: =+J8-1 -> 4 | K33: =+K8-2 -> 3 | L33: =SUM(C33:K33) -> 27 | M33: =+M8-1 -> 3 | N33: =+N8-1 -> 4 | O33: =+O8-1 -> 4 | P33: =+P8-1 -> 5 | Q33: =+Q8-2 -> 2 | R33: =+R8-1 -> 2 | S33: =+S8-2 -> 4 | T33: =+T8-1 -> 4 | U33: =+U8-2 -> 3 | V33: =SUM(M33:U33) -> 31 | W33: =+V33+L33 -> 58 | X33: =(0.5*12)-(0.5*3) -> 4.5 | Y33: =15*0.5 -> 7.5 | Z33: 15 | AA33: =SUM(X33:Z33) -> 27 | AB33: 11.8 | AC33: =SUM(AA33:AB33) -> 38.8
A34: =+A33+1 -> 7 | B34: =+B9 -> Leo | C34: =+C9-3 -> 8 | D34: =+D9-3 -> 4 | E34: =+E9-3 -> 6 | F34: =+F9-3 -> 6 | G34: =+G9-4 -> 0 | H34: =+H9-3 -> 2 | I34: =+I9-4 -> 6 | J34: =+J9-3 -> 6 | K34: =+K9-3 -> 3 | L34: =SUM(C34:K34) -> 41 | M34: =+M9-3 -> 4 | N34: =+N9-3 -> 4 | O34: =+O9-3 -> 5 | P34: =+P9-3 -> 6 | Q34: =+Q9-3 -> 1 | R34: =+R9-3 -> 4 | S34: =+S9-4 -> 4 | T34: =+T9-3 -> 4 | U34: =+U9-3 -> 5 | V34: =SUM(M34:U34) -> 37 | W34: =+V34+L34 -> 78 | X34: =15*0.5 -> 7.5 | Y34: =(0.5*3)-(0.5*12) -> -4.5 | Z34: =(1*11)-(1*3) -> 8 | AA34: =SUM(X34:Z34) -> 11 | AB34: -0.3 | AC34: =SUM(AA34:AB34) -> 10.7
A35: =+A34+1 -> 8 | B35: =+B10 -> Matt Lawrence | C35: =+C10-1 -> 4 | D35: =+D10 -> 4 | E35: =+E10 -> 5 | F35: =+F10-1 -> 7 | G35: =+G10-1 -> 2 | H35: =+H10-1 -> 3 | I35: =+I10-1 -> 3 | J35: =+J10-1 -> 4 | K35: =+K10-1 -> 4 | L35: =SUM(C35:K35) -> 36 | M35: =+M10-1 -> 4 | N35: =+N10 -> 6 | O35: =+O10 -> 5 | P35: =+P10-1 -> 5 | Q35: =+Q10-1 -> 3 | R35: =+R10-1 -> 3 | S35: =+S10-1 -> 4 | T35: =+T10-1 -> 7 | U35: =+U10-1 -> 4 | V35: =SUM(M35:U35) -> 41 | W35: =+V35+L35 -> 77 | X35: =(0.5*13)-(0.5*2) -> 5.5 | Y35: =(0.5*10)-(0.5*4) -> 3 | Z35: =(1*13)-(1*2) -> 11 | AA35: =SUM(X35:Z35) -> 19.5 | AB35: 7.3 | AC35: =SUM(AA35:AB35) -> 26.8
A36: =+A35+1 -> 9 | B36: =+B11 -> Jerry Flynn | C36: =+C11-1 -> 4 | D36: =+D11 -> 5 | E36: =+E11-1 -> 3 | F36: =+F11-1 -> 5 | G36: =+G11-1 -> 3 | H36: =+H11-1 -> 3 | I36: =+I11-1 -> 5 | J36: =+J11-1 -> 4 | K36: =+K11-1 -> 4 | L36: =SUM(C36:K36) -> 36 | M36: =+M11-1 -> 4 | N36: =+N11 -> 7 | O36: =+O11-1 -> 4 | P36: =+P11-1 -> 5 | Q36: =+Q11-1 -> 2 | R36: =+R11-1 -> 2 | S36: =+S11-1 -> 5 | T36: =+T11-1 -> 5 | U36: =+U11-1 -> 3 | V36: =SUM(M36:U36) -> 37 | W36: =+V36+L36 -> 73 | X36: =(0.5*4)-(0.5*11) -> -3.5 | Y36: =(0.5*1)-(0.5*13) -> -6 | Z36: =(1*1)-(1*14) -> -13 | AA36: =SUM(X36:Z36) -> -22.5 | AB36: -11.1 | AC36: =SUM(AA36:AB36) -> -33.6
A37: =+A36+1 -> 10 | B37: =+B12 -> Mike Flynn | C37: =+C12-1 -> 4 | D37: =+D12 -> 4 | E37: =+E12 -> 4 | F37: =+F12-1 -> 4 | G37: =+G12-1 -> 3 | H37: =+H12-1 -> 3 | I37: =+I12-1 -> 3 | J37: =+J12-1 -> 3 | K37: =+K12-1 -> 3 | L37: =SUM(C37:K37) -> 31 | M37: =+M12-1 -> 4 | N37: =+N12 -> 5 | O37: =+O12 -> 6 | P37: =+P12-1 -> 4 | Q37: =+Q12-1 -> 2 | R37: =+R12-1 -> 2 | S37: =+S12-1 -> 4 | T37: =+T12 -> 5 | U37: =+U12-1 -> 2 | V37: =SUM(M37:U37) -> 34 | W37: =+V37+L37 -> 65 | X37: =(0.5*11)-(0.5*4) -> 3.5 | Y37: =(0.5*6)-(0.5*9) -> -1.5 | Z37: =(1*9)-(1*6) -> 3 | AA37: =SUM(X37:Z37) -> 5 | AB37: -1.9 | AC37: =SUM(AA37:AB37) -> 3.1
A38: =+A37+1 -> 11 | B38: =+B13 -> Sean Flynn | C38: =+C13 -> 5 | D38: =+D13 -> 4 | E38: =+E13 -> 3 | F38: =+F13 -> 7 | G38: =+G13-1 -> 3 | H38: =+H13 -> 3 | I38: =+I13-1 -> 6 | J38: =+J13 -> 5 | K38: =+K13-1 -> 3 | L38: =SUM(C38:K38) -> 39 | M38: =+M13 -> 4 | N38: =+N13 -> 3 | O38: =+O13 -> 6 | P38: =+P13 -> 6 | Q38: =+Q13-1 -> 4 | R38: =+R13 -> 4 | S38: =+S13-1 -> 5 | T38: =+T13 -> 5 | U38: =+U13 -> 4 | V38: =SUM(M38:U38) -> 41 | W38: =+V38+L38 -> 80 | X38: -7.5 | Y38: -7.5 | Z38: -15 | AA38: =SUM(X38:Z38) -> -30 | AB38: -12 | AC38: =SUM(AA38:AB38) -> -42
A39: =+A38+1 -> 12 | B39: =+B14 -> Kevin Fitzgerald | C39: =+C14-1 -> 5 | D39: =+D14-1 -> 5 | E39: =+E14-1 -> 4 | F39: =+F14-2 -> 5 | G39: =+G14-2 -> 1 | H39: =+H14-1 -> 3 | I39: =+I14-2 -> 3 | J39: =+J14-1 -> 4 | K39: =+K14-2 -> 3 | L39: =SUM(C39:K39) -> 33 | M39: =+M14-1 -> 5 | N39: =+N14-1 -> 5 | O39: =+O14-1 -> 4 | P39: =+P14-1 -> 5 | Q39: =+Q14-2 -> 1 | R39: =+R14-1 -> 7 | S39: =+S14-2 -> 3 | T39: =+T14-1 -> 5 | U39: =+U14-2 -> 6 | V39: =SUM(M39:U39) -> 41 | W39: =+V39+L39 -> 74 | X39: =14*0.5-0.5 -> 6.5 | Y39: =(0.5*10)-(0.5*4) -> 3 | Z39: =(1*14)-(1*1) -> 13 | AA39: =SUM(X39:Z39) -> 22.5 | AB39: 12 | AC39: =SUM(AA39:AB39) -> 34.5
A40: =+A39+1 -> 13 | B40: =+B15 -> Richard McGovern | C40: =+C15-1 -> 4 | D40: =+D15-1 -> 4 | E40: =+E15-1 -> 5 | F40: =+F15-2 -> 4 | G40: =+G15-2 -> 3 | H40: =+H15-2 -> 2 | I40: =+I15-2 -> 4 | J40: =+J15-1 -> 6 | K40: =+K15-2 -> 3 | L40: =SUM(C40:K40) -> 35 | M40: =+M15-1 -> 6 | N40: =+N15-1 -> 4 | O40: =+O15-1 -> 6 | P40: =+P15-2 -> 5 | Q40: =+Q15-2 -> 1 | R40: =+R15-2 -> 2 | S40: =+S15-2 -> 4 | T40: =+T15-1 -> 4 | U40: =+U15-2 -> 3 | V40: =SUM(M40:U40) -> 35 | W40: =+V40+L40 -> 70 | X40: =(0.5*10)-(0.5*5) -> 2.5 | Y40: =(0.5*1)-(0.5*13) -> -6 | Z40: =(1*4)-(1*11) -> -7 | AA40: =SUM(X40:Z40) -> -10.5 | AB40: -1.5 | AC40: =SUM(AA40:AB40) -> -12
A41: =+A40+1 -> 14 | B41: =+B16 -> Mike Fitzgerald | C41: =+C16-1 -> 3 | D41: =+D16 -> 5 | E41: =+E16-1 -> 3 | F41: =+F16-1 -> 4 | G41: =+G16-1 -> 2 | H41: =+H16-1 -> 1 | I41: =+I16-1 -> 4 | J41: =+J16-1 -> 5 | K41: =+K16-1 -> 4 | L41: =SUM(C41:K41) -> 31 | M41: =+M16-1 -> 8 | N41: =+N16 -> 4 | O41: =+O16 -> 5 | P41: =+P16-1 -> 5 | Q41: =+Q16-1 -> 3 | R41: =+R16-1 -> 2 | S41: =+S16-1 -> 3 | T41: =+T16-1 -> 4 | U41: =+U16-1 -> 3 | V41: =SUM(M41:U41) -> 37 | W41: =+V41+L41 -> 68 | X41: =(0.5*2)-(0.5*12) -> -5 | Y41: =(0.5*7)-(0.5*7) -> 0 | Z41: =(1*3)-(1*12) -> -9 | AA41: =SUM(X41:Z41) -> -14 | AB41: -2.2 | AC41: =SUM(AA41:AB41) -> -16.2
...

Sheet 2021 day 2
X1: Day 2 | Y1: Day 2 | Z1: 2 DAY | AA1: Day 3
B2: Name | C2: 1 | D2: 2 | E2: 3 | F2: 4 | G2: 5 | H2: 6 | I2: 7 | J2: 8 | K2: 9 | L2: Front | M2: 10 | N2: 11 | O2: 12 | P2: 13 | Q2: 14 | R2: 15 | S2: 16 | T2: 17 | U2: 18 | V2: Back | W2: Total | X2: HDCP | Y2: Net | Z2: Net | AA2: HDCP
A3: 1 | B3: Colin Sullivan | C3: 5 | D3: 4 | E3: 5 | F3: 6 | G3: 6 | H3: 4 | I3: 6 | J3: 5 | K3: 6 | L3: =SUM(C3:K3) -> 47 | M3: 5 | N3: 7 | O3: 5 | P3: 7 | Q3: 3 | R3: 4 | S3: 6 | T3: 5 | U3: 6 | V3: =SUM(M3:U3) -> 48 | W3: =+L3+V3 -> 95 | X3: 29.75 | Y3: =+W3-X3 -> 65.25 | Z3: =+Y3+'day 1'!Z3 -> 133.25 | AA3: =(W3-70)*0.875 -> 21.875
A4: =+A3+1 -> 2 | B4: Bernie Sullivan | C4: 5 | D4: 6 | E4: 5 | F4: 5 | G4: 5 | H4: 4 | I4: 6 | J4: 6 | K4: 6 | L4: =SUM(C4:K4) -> 48 | M4: 4 | N4: 6 | O4: 4 | P4: 7 | Q4: 3 | R4: 5 | S4: 4 | T4: 5 | U4: 5 | V4: =SUM(M4:U4) -> 43 | W4: =+L4+V4 -> 91 | X4: 14 | Y4: =+W4-X4 -> 77 | Z4: =+Y4+'day 1'!Z4 -> 140.25 | AA4: =(W4-70)*0.875 -> 18.375
A5: =+A4+1 -> 3 | B5: Joe McCardel | C5: 4 | D5: 6 | E5: 7 | F5: 8 | G5: 4 | H5: 4 | I5: 7 | J5: 6 | K5: 4 | L5: =SUM(C5:K5) -> 50 | M5: 5 | N5: 7 | O5: 5 | P5: 9 | Q5: 4 | R5: 4 | S5: 6 | T5: 6 | U5: 4 | V5: =SUM(M5:U5) -> 50 | W5: =+L5+V5 -> 100 | X5: 30.625 | Y5: =+W5-X5 -> 69.375 | Z5: =+Y5+'day 1'!Z5 -> 144.625 | AA5: =(W5-70)*0.875 -> 26.25
A6: =+A5+1 -> 4 | B6: Dave Brauer | C6: 4 | D6: 5 | E6: 5 | F6: 5 | G6: 4 | H6: 3 | I6: 6 | J6: 5 | K6: 5 | L6: =SUM(C6:K6) -> 42 | M6: 4 | N6: 4 | O6: 5 | P6: 7 | Q6: 3 | R6: 4 | S6: 4 | T6: 5 | U6: 6 | V6: =SUM(M6:U6) -> 42 | W6: =+L6+V6 -> 84 | X6: 15.75 | Y6: =+W6-X6 -> 68.25 | Z6: =+Y6+'day 1'!Z6 -> 136.125 | AA6: =(W6-70)*0.875 -> 12.25
A7: =+A6+1 -> 5 | B7: John Sullivan | C7: 4 | D7: 4 | E7: 6 | F7: 5 | G7: 4 | H7: 5 | I7: 5 | J7: 6 | K7: 6 | L7: =SUM(C7:K7) -> 45 | M7: 5 | N7: 5 | O7: 5 | P7: 8 | Q7: 4 | R7: 4 | S7: 4 | T7: 6 | U7: 5 | V7: =SUM(M7:U7) -> 46 | W7: =+L7+V7 -> 91 | X7: 21.875 | Y7: =+W7-X7 -> 69.125 | Z7: =+Y7+'day 1'!Z7 -> 145.75 | AA7: =(W7-70)*0.875 -> 18.375
A8: =+A7+1 -> 6 | B8: Ralph | C8: 4 | D8: 3 | E8: 6 | F8: 5 | G8: 4 | H8: 4 | I8: 6 | J8: 5 | K8: 7 | L8: =SUM(C8:K8) -> 44 | M8: 6 | N8: 6 | O8: 5 | P8: 5 | Q8: 6 | R8: 4 | S8: 5 | T8: 5 | U8: 5 | V8: =SUM(M8:U8) -> 47 | W8: =+L8+V8 -> 91 | X8: 11.375 | Y8: =+W8-X8 -> 79.625 | Z8: =+Y8+'day 1'!Z8 -> 138.125 | AA8: =(W8-70)*0.875 -> 18.375
A9: =+A8+1 -> 7 | B9: Leo | C9: 9 | D9: 6 | E9: 8 | F9: 8 | G9: 6 | H9: 9 | I9: 10 | J9: 6 | K9: 5 | L9: =SUM(C9:K9) -> 67 | M9: 6 | N9: 7 | O9: 5 | P9: 7 | Q9: 7 | R9: 8 | S9: 7 | T9: 5 | U9: 8 | V9: =SUM(M9:U9) -> 60 | W9: =+L9+V9 -> 127 | X9: 56.875 | Y9: =+W9-X9 -> 70.125 | Z9: =+Y9+'day 1'!Z9 -> 148.25 | AA9: =(W9-70)*0.875 -> 49.875
A10: =+A9+1 -> 8 | B10: Matt Lawrence | C10: 6 | D10: 6 | E10: 5 | F10: 5 | G10: 3 | H10: 4 | I10: 5 | J10: 5 | K10: 6 | L10: =SUM(C10:K10) -> 45 | M10: 4 | N10: 7 | O10: 5 | P10: 6 | Q10: 5 | R10: 4 | S10: 5 | T10: 4 | U10: 6 | V10: =SUM(M10:U10) -> 46 | W10: =+L10+V10 -> 91 | X10: 18.375 | Y10: =+W10-X10 -> 72.625 | Z10: =+Y10+'day 1'!Z10 -> 148.75 | AA10: =(W10-70)*0.875 -> 18.375
A11: =+A10+1 -> 9 | B11: Jerry Flynn | C11: 5 | D11: 4 | E11: 4 | F11: 6 | G11: 3 | H11: 3 | I11: 6 | J11: 6 | K11: 5 | L11: =SUM(C11:K11) -> 42 | M11: 6 | N11: 5 | O11: 5 | P11: 7 | Q11: 5 | R11: 3 | S11: 7 | T11: 5 | U11: 5 | V11: =SUM(M11:U11) -> 48 | W11: =+L11+V11 -> 90 | X11: 16.625 | Y11: =+W11-X11 -> 73.375 | Z11: =+Y11+'day 1'!Z11 -> 146.625 | AA11: =(W11-70)*0.875 -> 17.5
A12: =+A11+1 -> 10 | B12: Mike Flynn | C12: 4 | D12: 4 | E12: 5 | F12: 5 | G12: 4 | H12: 3 | I12: 4 | J12: 4 | K12: 4 | L12: =SUM(C12:K12) -> 37 | M12: 5 | N12: 4 | O12: 4 | P12: 6 | Q12: 2 | R12: 3 | S12: 6 | T12: 5 | U12: 4 | V12: =SUM(M12:U12) -> 39 | W12: =+L12+V12 -> 76 | X12: 7 | Y12: =+W12-X12 -> 69 | Z12: =+Y12+'day 1'!Z12 -> 133.875 | AA12: =(W12-70)*0.875 -> 5.25
A13: =+A12+1 -> 11 | B13: Sean Flynn | C13: 4 | D13: 5 | E13: 4 | F13: 5 | G13: 3 | H13: 4 | I13: 5 | J13: 5 | K13: 6 | L13: =SUM(C13:K13) -> 41 | M13: 4 | N13: 5 | O13: 6 | P13: 5 | Q13: 3 | R13: 3 | S13: 5 | T13: 5 | U13: 4 | V13: =SUM(M13:U13) -> 40 | W13: =+L13+V13 -> 81 | X13: 13.125 | Y13: =+W13-X13 -> 67.875 | Z13: =+Y13+'day 1'!Z13 -> 147.875 | AA13: =(W13-70)*0.875 -> 9.625
A14: =+A13+1 -> 12 | B14: Kevin Fitzgerald | C14: 4 | D14: 3 | E14: 5 | F14: 6 | G14: 3 | H14: 5 | I14: 5 | J14: 5 | K14: 6 | L14: =SUM(C14:K14) -> 42 | M14: 5 | N14: 7 | O14: 5 | P14: 7 | Q14: 4 | R14: 3 | S14: 6 | T14: 5 | U14: 6 | V14: =SUM(M14:U14) -> 48 | W14: =+L14+V14 -> 90 | X14: 25.375 | Y14: =+W14-X14 -> 64.625 | Z14: =+Y14+'day 1'!Z14 -> 138.25 | AA14: =(W14-70)*0.875 -> 17.5
A15: =+A14+1 -> 13 | B15: Richard McGovern | C15: 7 | D15: 6 | E15: 5 | F15: 7 | G15: 4 | H15: 4 | I15: 6 | J15: 7 | K15: 3 | L15: =SUM(C15:K15) -> 49 | M15: 6 | N15: 5 | O15: 7 | P15: 7 | Q15: 4 | R15: 4 | S15: 7 | T15: 5 | U15: 5 | V15: =SUM(M15:U15) -> 50 | W15: =+L15+V15 -> 99 | X15: 24.5 | Y15: =+W15-X15 -> 74.5 | Z15: =+Y15+'day 1'!Z15 -> 144.5 | AA15: =(W15-70)*0.875 -> 25.375
... A20: =+A19+1 -> 18 | B20: TJ Williams | C20: 5 | D20: 4 | E20: 7 | F20: 7 | G20: 5 | H20: 4 | I20: 5 | J20: 6 | K20: 5 | L20: =SUM(C20:K20) -> 48 | M20: 5 | N20: 5 | O20: 4 | P20: 7 | Q20: 5 | R20: 4 | S20: 7 | T20: 7 | U20: 7 | V20: =SUM(M20:U20) -> 51 | W20: =+L20+V20 -> 99 | X20: 25.375 | Y20: =+W20-X20 -> 73.625 | Z20: =+Y20+'day 1'!Z20 -> 172.625 | AA20: =(W20-70)*0.875 -> 25.375
A21: =+A20+1 -> 19 | B21: Brian McGovern | L21: =SUM(C21:K21) -> 0 | V21: =SUM(M21:U21) -> 0 | W21: =+L21+V21 -> 0 | X21: 15.75 | Y21: =+W21-X21 -> -15.75 | Z21: =+Y21+'day 1'!Z21 -> 57.25 | AA21: =(W21-70)*0.875 -> -61.25
A22: =+A21+1 -> 20 | B22: Dave Keyser | C22: 5 | D22: 4 | E22: 8 | F22: 7 | G22: 5 | H22: 4 | I22: 7 | J22: 6 | K22: 6 | L22: =SUM(C22:K22) -> 52 | M22: 5 | N22: 7 | O22: 7 | P22: 7 | Q22: 4 | R22: 5 | S22: 6 | T22: 7 | U22: 6 | V22: =SUM(M22:U22) -> 54 | W22: =+L22+V22 -> 106 | X22: 28 | Y22: =+W22-X22 -> 78 | Z22: =+Y22+'day 1'!Z22 -> 156 | AA22: =(W22-70)*0.875 -> 31.5
A23: =+A22+1 -> 21 | B23: Jack Sullivan | C23: 7 | D23: 6 | E23: 6 | F23: 8 | G23: 4 | H23: 4 | I23: 7 | J23: 6 | K23: 5 | L23: =SUM(C23:K23) -> 53 | M23: 4 | N23: 5 | O23: 7 | P23: 7 | Q23: 3 | R23: 3 | S23: 6 | T23: 7 | U23: 5 | V23: =SUM(M23:U23) -> 47 | W23: =+L23+V23 -> 100 | X23: 34.125 | Y23: =+W23-X23 -> 65.875 | Z23: =+Y23+'day 1'!Z23 -> 143.875 | AA23: =(W23-70)*0.875 -> 26.25
A24: =+A23+1 -> 22 | B24: Chris Flynn | C24: 5 | D24: 9 | E24: 5 | F24: 5 | G24: 5 | H24: 3 | I24: 6 | J24: 5 | K24: 4 | L24: =SUM(C24:K24) -> 47 | M24: 4 | N24: 9 | O24: 4 | P24: 6 | Q24: 5 | R24: 4 | S24: 4 | T24: 5 | U24: 4 | V24: =SUM(M24:U24) -> 45 | W24: =+L24+V24 -> 92 | X24: 21.875 | Y24: =+W24-X24 -> 70.125 | Z24: =+Y24+'day 1'!Z24 -> 141.125 | AA24: =(W24-70)*0.875 -> 19.25
B25: HDCP | C25: 11 | D25: 17 | E25: 15 | F25: 7 | G25: 3 | H25: 9 | I25: 1 | J25: 13 | K25: 5 | M25: 12 | N25: 18 | O25: 16 | P25: 8 | Q25: 4 | R25: 10 | S25: 2 | T25: 14 | U25: 6
B27: Net of HDCP
A28: 1 | B28: =+B3 -> Colin Sullivan | C28: =+C3-2 -> 3 | D28: =+D3-1 -> 3 | E28: =+E3-1 -> 4 | F28: =+F3-2 -> 4 | G28: =+G3-2 -> 4 | H28: =+H3-2 -> 2 | I28: =+I3-2 -> 4 | J28: =+J3-1 -> 4 | K28: =+K3-2 -> 4 | L28: =SUM(C28:K28) -> 32 | M28: =+M3-2 -> 3 | N28: =+N3-1 -> 6 | O28: =+O3-1 -> 4 | P28: =+P3-2 -> 5 | Q28: =+Q3-2 -> 1 | R28: =+R3-2 -> 2 | S28: =+S3-2 -> 4 | T28: =+T3-1 -> 4 | U28: =+U3-2 -> 4 | V28: =SUM(M28:U28) -> 33 | W28: =+V28+L28 -> 65 | X28: =(0.5*6)-(0.5*6) -> 0 | Y28: =(0.5*4)-(0.5*10) -> -3 | Z28: =(1*5)-(1*9) -> -4 | AA28: =SUM(X28:Z28) -> -7 | AB28: -2.6 | AC28: =SUM(AA28:AB28) -> -9.6
A29: =+A28+1 -> 2 | B29: =+B4 -> Bernie Sullivan | C29: =+C4-1 -> 4 | D29: =+D4 -> 6 | E29: =+E4-1 -> 4 | F29: =+F4-1 -> 4 | G29: =+G4-1 -> 4 | H29: =+H4-1 -> 3 | I29: =+I4-1 -> 5 | J29: =+J4-1 -> 5 | K29: =+K4-1 -> 5 | L29: =SUM(C29:K29) -> 40 | M29: =+M4-1 -> 3 | N29: =+N4 -> 6 | O29: =+O4 -> 4 | P29: =+P4-1 -> 6 | Q29: =+Q4-1 -> 2 | R29: =+R4-1 -> 4 | S29: =+S4-1 -> 3 | T29: =+T4-1 -> 4 | U29: =+U4-1 -> 4 | V29: =SUM(M29:U29) -> 36 | W29: =+V29+L29 -> 76 | X29: =(0.5*6)-(0.5*6) -> 0 | Y29: =(0.5*4)-(0.5*10) -> -3 | Z29: =(1*5)-(1*9) -> -4 | AA29: =SUM(X29:Z29) -> -7 | AB29: -4.7 | AC29: =SUM(AA29:AB29) -> -11.7
A30: =+A29+1 -> 3 | B30: =+B5 -> Joe McCardel | C30: =+C5-2 -> 2 | D30: =+D5-1 -> 5 | E30: =+E5-1 -> 6 | F30: =+F5-2 -> 6 | G30: =+G5-2 -> 2 | H30: =+H5-2 -> 2 | I30: =+I5-2 -> 5 | J30: =+J5-2 -> 4 | K30: =+K5-2 -> 2 | L30: =SUM(C30:K30) -> 34 | M30: =+M5-2 -> 3 | N30: =+N5-1 -> 6 | O30: =+O5-1 -> 4 | P30: =+P5-2 -> 7 | Q30: =+Q5-2 -> 2 | R30: =+R5-2 -> 2 | S30: =+S5-2 -> 4 | T30: =+T5-1 -> 5 | U30: =+U5-2 -> 2 | V30: =SUM(M30:U30) -> 35 | W30: =+V30+L30 -> 69 | X30: =(0.5*2)-(0.5*12) -> -5 | Y30: =(0.5*13)-(0.5*1) -> 6 | Z30: =(1*8)-(1*7) -> 1 | AA30: =SUM(X30:Z30) -> 2 | AB30: -0.3 | AC30: =SUM(AA30:AB30) -> 1.7
A31: =+A30+1 -> 4 | B31: =+B6 -> Dave Brauer | C31: =+C6-1 -> 3 | D31: =+D6 -> 5 | E31: =+E6-1 -> 4 | F31: =+F6-1 -> 4 | G31: =+G6-1 -> 3 | H31: =+H6-1 -> 2 | I31: =+I6-1 -> 5 | J31: =+J6-1 -> 4 | K31: =+K6-1 -> 4 | L31: =SUM(C31:K31) -> 34 | M31: =+M6-1 -> 3 | N31: =+N6 -> 4 | O31: =+O6-1 -> 4 | P31: =+P6-1 -> 6 | Q31: =+Q6-1 -> 2 | R31: =+R6-1 -> 3 | S31: =+S6-1 -> 3 | T31: =+T6-1 -> 4 | U31: =+U6-1 -> 5 | V31: =SUM(M31:U31) -> 34 | W31: =+V31+L31 -> 68 | X31: =(0.5*6)-(0.5*6) -> 0 | Y31: =(0.5*13)-(0.5*1) -> 6 | Z31: =(1*11)-(1*3) -> 8 | AA31: =SUM(X31:Z31) -> 14 | AB31: 4.9 | AC31: =SUM(AA31:AB31) -> 18.9
A32: =+A31+1 -> 5 | B32: =+B7 -> John Sullivan | C32: =+C7-1 -> 3 | D32: =+D7-1 -> 3 | E32: =+E7-1 -> 5 | F32: =+F7-1 -> 4 | G32: =+G7-2 -> 2 | H32: =+H7-1 -> 4 | I32: =+I7-2 -> 3 | J32: =+J7-1 -> 5 | K32: =+K7-1 -> 5 | L32: =SUM(C32:K32) -> 34 | M32: =+M7-1 -> 4 | N32: =+N7-1 -> 4 | O32: =+O7-1 -> 4 | P32: =+P7-1 -> 7 | Q32: =+Q7-2 -> 2 | R32: =+R7-1 -> 3 | S32: =+S7-2 -> 2 | T32: =+T7-1 -> 5 | U32: =+U7-1 -> 4 | V32: =SUM(M32:U32) -> 35 | W32: =+V32+L32 -> 69 | X32: =(0.5*6)-(0.5*6) -> 0 | Y32: =(0.5*12)-(0.5*3) -> 4.5 | Z32: =(1*10)-(1*5) -> 5 | AA32: =SUM(X32:Z32) -> 9.5 | AB32: 4.9 | AC32: =SUM(AA32:AB32) -> 14.4
A33: =+A32+1 -> 6 | B33: =+B8 -> Ralph | C33: =+C8-1 -> 3 | D33: =+D8 -> 3 | E33: =+E8 -> 6 | F33: =+F8-1 -> 4 | G33: =+G8-1 -> 3 | H33: =+H8-1 -> 3 | I33: =+I8-1 -> 5 | J33: =+J8 -> 5 | K33: =+K8-1 -> 6 | L33: =SUM(C33:K33) -> 38 | M33: =+M8 -> 6 | N33: =+N8 -> 6 | O33: =+O8 -> 5 | P33: =+P8-1 -> 4 | Q33: =+Q8-1 -> 5 | R33: =+R8-1 -> 3 | S33: =+S8-1 -> 4 | T33: =+T8 -> 5 | U33: =+U8-1 -> 4 | V33: =SUM(M33:U33) -> 42 | W33: =+V33+L33 -> 80 | X33: =(0.5*12)-(0.5*3) -> 4.5 | Y33: =15*0.5 -> 7.5 | Z33: 15 | AA33: =SUM(X33:Z33) -> 27 | AB33: 11.8 | AC33: =SUM(AA33:AB33) -> 38.8
A34: =+A33+1 -> 7 | B34: =+B9 -> Leo | C34: =+C9-3 -> 6 | D34: =+D9-3 -> 3 | E34: =+E9-3 -> 5 | F34: =+F9-3 -> 5 | G34: =+G9-4 -> 2 | H34: =+H9-3 -> 6 | I34: =+I9-4 -> 6 | J34: =+J9-3 -> 3 | K34: =+K9-3 -> 2 | L34: =SUM(C34:K34) -> 38 | M34: =+M9-3 -> 3 | N34: =+N9-3 -> 4 | O34: =+O9-3 -> 2 | P34: =+P9-3 -> 4 | Q34: =+Q9-3 -> 4 | R34: =+R9-3 -> 5 | S34: =+S9-4 -> 3 | T34: =+T9-3 -> 2 | U34: =+U9-3 -> 5 | V34: =SUM(M34:U34) -> 32 | W34: =+V34+L34 -> 70 | X34: =15*0.5 -> 7.5 | Y34: =(0.5*3)-(0.5*12) -> -4.5 | Z34: =(1*11)-(1*3) -> 8 | AA34: =SUM(X34:Z34) -> 11 | AB34: -0.3 | AC34: =SUM(AA34:AB34) -> 10.7
A35: =+A34+1 -> 8 | B35: =+B10 -> Matt Lawrence | C35: =+C10-1 -> 5 | D35: =+D10-1 -> 5 | E35: =+E10-1 -> 4 | F35: =+F10-1 -> 4 | G35: =+G10-1 -> 2 | H35: =+H10-1 -> 3 | I35: =+I10-1 -> 4 | J35: =+J10-1 -> 4 | K35: =+K10-1 -> 5 | L35: =SUM(C35:K35) -> 36 | M35: =+M10-1 -> 3 | N35: =+N10-1 -> 6 | O35: =+O10-1 -> 4 | P35: =+P10-1 -> 5 | Q35: =+Q10-1 -> 4 | R35: =+R10-1 -> 3 | S35: =+S10-1 -> 4 | T35: =+T10-1 -> 3 | U35: =+U10-1 -> 5 | V35: =SUM(M35:U35) -> 37 | W35: =+V35+L35 -> 73 | X35: =(0.5*13)-(0.5*2) -> 5.5 | Y35: =(0.5*10)-(0.5*4) -> 3 | Z35: =(1*13)-(1*2) -> 11 | AA35: =SUM(X35:Z35) -> 19.5 | AB35: 7.3 | AC35: =SUM(AA35:AB35) -> 26.8
A36: =+A35+1 -> 9 | B36: =+B11 -> Jerry Flynn | C36: =+C11-1 -> 4 | D36: =+D11-1 -> 3 | E36: =+E11-1 -> 3 | F36: =+F11-1 -> 5 | G36: =+G11-1 -> 2 | H36: =+H11-1 -> 2 | I36: =+I11-1 -> 5 | J36: =+J11-1 -> 5 | K36: =+K11-1 -> 4 | L36: =SUM(C36:K36) -> 33 | M36: =+M11-1 -> 5 | N36: =+N11 -> 5 | O36: =+O11-1 -> 4 | P36: =+P11-1 -> 6 | Q36: =+Q11-1 -> 4 | R36: =+R11-1 -> 2 | S36: =+S11-1 -> 6 | T36: =+T11-1 -> 4 | U36: =+U11-1 -> 4 | V36: =SUM(M36:U36) -> 40 | W36: =+V36+L36 -> 73 | X36: =(0.5*4)-(0.5*11) -> -3.5 | Y36: =(0.5*1)-(0.5*13) -> -6 | Z36: =(1*1)-(1*14) -> -13 | AA36: =SUM(X36:Z36) -> -22.5 | AB36: -11.1 | AC36: =SUM(AA36:AB36) -> -33.6
A37: =+A36+1 -> 10 | B37: =+B12 -> Mike Flynn | C37: =+C12 -> 4 | D37: =+D12 -> 4 | E37: =+E12 -> 5 | F37: =+F12-1 -> 4 | G37: =+G12-1 -> 3 | H37: =+H12 -> 3 | I37: =+I12-1 -> 3 | J37: =+J12 -> 4 | K37: =+K12-1 -> 3 | L37: =SUM(C37:K37) -> 33 | M37: =+M12 -> 5 | N37: =+N12 -> 4 | O37: =+O12 -> 4 | P37: =+P12 -> 6 | Q37: =+Q12-1 -> 1 | R37: =+R12 -> 3 | S37: =+S12-1 -> 5 | T37: =+T12 -> 5 | U37: =+U12-1 -> 3 | V37: =SUM(M37:U37) -> 36 | W37: =+V37+L37 -> 69 | X37: =(0.5*11)-(0.5*4) -> 3.5 | Y37: =(0.5*6)-(0.5*9) -> -1.5 | Z37: =(1*9)-(1*6) -> 3 | AA37: =SUM(X37:Z37) -> 5 | AB37: -1.9 | AC37: =SUM(AA37:AB37) -> 3.1
A38: =+A37+1 -> 11 | B38: =+B13 -> Sean Flynn | C38: =+C13-1 -> 3 | D38: =+D13 -> 5 | E38: =+E13 -> 4 | F38: =+F13-1 -> 4 | G38: =+G13-1 -> 2 | H38: =+H13-1 -> 3 | I38: =+I13-1 -> 4 | J38: =+J13-1 -> 4 | K38: =+K13-1 -> 5 | L38: =SUM(C38:K38) -> 34 | M38: =+M13-1 -> 3 | N38: =+N13 -> 5 | O38: =+O13 -> 6 | P38: =+P13-1 -> 4 | Q38: =+Q13-1 -> 2 | R38: =+R13-1 -> 2 | S38: =+S13-1 -> 4 | T38: =+T13 -> 5 | U38: =+U13-1 -> 3 | V38: =SUM(M38:U38) -> 34 | W38: =+V38+L38 -> 68 | X38: -7.5 | Y38: -7.5 | Z38: -15 | AA38: =SUM(X38:Z38) -> -30 | AB38: -12 | AC38: =SUM(AA38:AB38) -> -42
A39: =+A38+1 -> 12 | B39: =+B14 -> Kevin Fitzgerald | C39: =+C14-1 -> 3 | D39: =+D14-1 -> 2 | E39: =+E14-1 -> 4 | F39: =+F14-2 -> 4 | G39: =+G14-2 -> 1 | H39: =+H14-1 -> 4 | I39: =+I14-2 -> 3 | J39: =+J14-1 -> 4 | K39: =+K14-2 -> 4 | L39: =SUM(C39:K39) -> 29 | M39: =+M14-1 -> 4 | N39: =+N14-1 -> 6 | O39: =+O14-1 -> 4 | P39: =+P14-1 -> 6 | Q39: =+Q14-2 -> 2 | R39: =+R14-1 -> 2 | S39: =+S14-2 -> 4 | T39: =+T14-1 -> 4 | U39: =+U14-2 -> 4 | V39: =SUM(M39:U39) -> 36 | W39: =+V39+L39 -> 65 | X39: =14*0.5-0.5 -> 6.5 | Y39: =(0.5*10)-(0.5*4) -> 3 | Z39: =(1*14)-(1*1) -> 13 | AA39: =SUM(X39:Z39) -> 22.5 | AB39: 12 | AC39: =SUM(AA39:AB39) -> 34.5
A40: =+A39+1 -> 13 | B40: =+B15 -> Richard McGovern | C40: =+C15-1 -> 6 | D40: =+D15-1 -> 5 | E40: =+E15-1 -> 4 | F40: =+F15-2 -> 5 | G40: =+G15-2 -> 2 | H40: =+H15-1 -> 3 | I40: =+I15-2 -> 4 | J40: =+J15-1 -> 6 | K40: =+K15-2 -> 1 | L40: =SUM(C40:K40) -> 36 | M40: =+M15-1 -> 5 | N40: =+N15-1 -> 4 | O40: =+O15-1 -> 6 | P40: =+P15-1 -> 6 | Q40: =+Q15-2 -> 2 | R40: =+R15-1 -> 3 | S40: =+S15-2 -> 5 | T40: =+T15-1 -> 4 | U40: =+U15-2 -> 3 | V40: =SUM(M40:U40) -> 38 | W40: =+V40+L40 -> 74 | X40: =(0.5*10)-(0.5*5) -> 2.5 | Y40: =(0.5*1)-(0.5*13) -> -6 | Z40: =(1*4)-(1*11) -> -7 | AA40: =SUM(X40:Z40) -> -10.5 | AB40: -1.5 | AC40: =SUM(AA40:AB40) -> -12
A41: =+A40+1 -> 14 | B41: =+B16 -> Mike Fitzgerald | C41: =+C16-1 -> 4 | D41: =+D16 -> 4 | E41: =+E16 -> 6 | F41: =+F16-1 -> 5 | G41: =+G16-1 -> 3 | H41: =+H16-1 -> 3 | I41: =+I16-1 -> 3 | J41: =+J16 -> 5 | K41: =+K16-1 -> 3 | L41: =SUM(C41:K41) -> 36 | M41: =+M16 -> 4 | N41: =+N16 -> 6 | O41: =+O16 -> 5 | P41: =+P16-1 -> 3 | Q41: =+Q16-1 -> 2 | R41: =+R16-1 -> 3 | S41: =+S16-1 -> 3 | T41: =+T16 -> 3 | U41: =+U16-1 -> 4 | V41: =SUM(M41:U41) -> 33 | W41: =+V41+L41 -> 69 | X41: =(0.5*2)-(0.5*12) -> -5 | Y41: =(0.5*7)-(0.5*7) -> 0 | Z41: =(1*3)-(1*12) -> -9 | AA41: =SUM(X41:Z41) -> -14 | AB41: -2.2 | AC41: =SUM(AA41:AB41) -> -16.2
A42: =+A41+1 -> 15 | B42: =+B17 -> Matt Brauer | C42: =+C17 -> 4 | D42: =+D17 -> 5 | E42: =+E17 -> 7 | F42: =+F17-1 -> 5 | G42: =+G17-1 -> 3 | H42: =+H17 -> 3 | I42: =+I17 -> 5 | J42: =+J17 -> 5 | K42: =+K17-1 -> 2 | L42: =SUM(C42:K42) -> 39 | M42: =+M17 -> 5 | N42: =+N17 -> 5 | O42: =+O17 -> 5 | P42: =+P17 -> 6 | Q42: =+Q17-1 -> 2 | R42: =+R17 -> 3 | S42: =+S17-1 -> 3 | T42: =+T17 -> 4 | U42: =+U17-1 -> 3 | V42: =SUM(M42:U42) -> 36 | W42: =+V42+L42 -> 75 | Z42: =(1*3)-(1*12) -> -9 | AA42: =SUM(X42:Z42) -> -9 | AB42: -2.2 | AC42: =SUM(AA42:AB42) -> -11.2
A43: =+A42+1 -> 16 | B43: =+B18 -> Blake Dougan | C43: =+C18-1 -> 6 | D43: =+D18-1 -> 6 | E43: =+E18-1 -> 3 | F43: =+F18-2 -> 7 | G43: =+G18-2 -> 3 | H43: =+H18-2 -> 3 | I43: =+I18-2 -> 2 | J43: =+J18-1 -> 4 | K43: =+K18-2 -> 2 | L43: =SUM(C43:K43) -> 36 | M43: =+M18-1 -> 5 | N43: =+N18-1 -> 5 | O43: =+O18-1 -> 6 | P43: =+P18-2 -> 6 | Q43: =+Q18-2 -> 1 | R43: =+R18-2 -> 1 | S43: =+S18-2 -> 6 | T43: =+T18-1 -> 5 | U43: =+U18-2 -> 3 | V43: =SUM(M43:U43) -> 38 | W43: =+V43+L43 -> 74 | Z43: =(1*3)-(1*12) -> -9 | AA43: =SUM(X43:Z43) -> -9 | AB43: -2.2 | AC43: =SUM(AA43:AB43) -> -11.2
A44: =+A43+1 -> 17 | B44: =+B19 -> Mike Dougan | C44: =+C19-1 -> 5 | D44: =+D19-1 -> 4 | E44: =+E19-1 -> 5 | F44: =+F19-1 -> 6 | G44: =+G19-2 -> 1 | H44: =+H19-1 -> 3 | I44: =+I19-2 -> 3 | J44: =+J19-1 -> 5 | K44: =+K19-2 -> 3 | L44: =SUM(C44:K44) -> 35 | M44: =+M19-1 -> 5 | N44: =+N19-1 -> 5 | O44: =+O19-1 -> 5 | P44: =+P19-1 -> 6 | Q44: =+Q19-2 -> 1 | R44: =+R19-1 -> 4 | S44: =+S19-2 -> 3 | T44: =+T19-1 -> 4 | U44: =+U19-2 -> 5 | V44: =SUM(M44:U44) -> 38 | W44: =+V44+L44 -> 73 | Z44: =(1*3)-(1*12) -> -9 | AA44: =SUM(X44:Z44) -> -9 | AB44: -2.2 | AC44: =SUM(AA44:AB44) -> -11.2
A45: =+A44+1 -> 18 | B45: =+B20 -> TJ Williams | C45: =+C20-1 -> 4 | D45: =+D20-1 -> 3 | E45: =+E20-1 -> 6 | F45: =+F20-2 -> 5 | G45: =+G20-2 -> 3 | H45: =+H20-1 -> 3 | I45: =+I20-2 -> 3 | J45: =+J20-1 -> 5 | K45: =+K20-2 -> 3 | L45: =SUM(C45:K45) -> 35 | M45: =+M20-1 -> 4 | N45: =+N20-1 -> 4 | O45: =+O20-1 -> 3 | P45: =+P20-1 -> 6 | Q45: =+Q20-2 -> 3 | R45: =+R20-1 -> 3 | S45: =+S20-2 -> 5 | T45: =+T20-1 -> 6 | U45: =+U20-2 -> 5 | V45: =SUM(M45:U45) -> 39 | W45: =+V45+L45 -> 74 | Z45: =(1*3)-(1*12) -> -9 | AA45: =SUM(X45:Z45) -> -9 | AB45: -2.2 | AC45: =SUM(AA45:AB45) -> -11.2
...

Sheet 2021 day 3
X1: Day 3 | Y1: Day 2 | Z1: 3 DAY | AA1: 2022
B2: Name | C2: 1 | D2: 2 | E2: 3 | F2: 4 | G2: 5 | H2: 6 | I2: 7 | J2: 8 | K2: 9 | L2: Front | M2: 10 | N2: 11 | O2: 12 | P2: 13 | Q2: 14 | R2: 15 | S2: 16 | T2: 17 | U2: 18 | V2: Back | W2: Total | X2: HDCP | Y2: Net | Z2: Net | AA2: HDCP
A3: 1 | B3: Colin Sullivan | C3: 5 | D3: 4 | E3: 5 | F3: 6 | G3: 4 | H3: 4 | I3: 7 | J3: 5 | K3: 5 | L3: =SUM(C3:K3) -> 45 | M3: 6 | N3: 6 | O3: 7 | P3: 5 | Q3: 3 | R3: 4 | S3: 6 | T3: 5 | U3: 4 | V3: =SUM(M3:U3) -> 46 | W3: =+L3+V3 -> 91 | X3: 21.875 | Y3: =+W3-X3 -> 69.125 | Z3: =+Y3+'2021 day 2'!Z3 -> 202.375 | AA3: =(W3-70)*0.875 -> 18.375
A4: =+A3+1 -> 2 | B4: Bernie Sullivan | C4: 4 | D4: 4 | E4: 6 | F4: 7 | G4: 3 | H4: 4 | I4: 5 | J4: 5 | K4: 5 | L4: =SUM(C4:K4) -> 43 | M4: 4 | N4: 5 | O4: 6 | P4: 7 | Q4: 3 | R4: 4 | S4: 6 | T4: 5 | U4: 5 | V4: =SUM(M4:U4) -> 45 | W4: =+L4+V4 -> 88 | X4: 18.375 | Y4: =+W4-X4 -> 69.625 | Z4: =+Y4+'2021 day 2'!Z4 -> 209.875 | AA4: =(W4-70)*0.875 -> 15.75
A5: =+A4+1 -> 3 | B5: Joe McCardel | C5: 4 | D5: 7 | E5: 6 | F5: 6 | G5: 9 | H5: 4 | I5: 7 | J5: 5 | K5: 4 | L5: =SUM(C5:K5) -> 52 | M5: 5 | N5: 7 | O5: 7 | P5: 5 | Q5: 2 | R5: 3 | S5: 8 | T5: 7 | U5: 5 | V5: =SUM(M5:U5) -> 49 | W5: =+L5+V5 -> 101 | X5: 26.25 | Y5: =+W5-X5 -> 74.75 | Z5: =+Y5+'2021 day 2'!Z5 -> 219.375 | AA5: =(W5-70)*0.875 -> 27.125
A6: =+A5+1 -> 4 | B6: Dave Brauer | C6: 5 | D6: 5 | E6: 6 | F6: 7 | G6: 3 | H6: 4 | I6: 5 | J6: 7 | K6: 7 | L6: =SUM(C6:K6) -> 49 | M6: 5 | N6: 5 | O6: 5 | P6: 7 | Q6: 4 | R6: 4 | S6: 6 | T6: 6 | U6: 6 | V6: =SUM(M6:U6) -> 48 | W6: =+L6+V6 -> 97 | X6: 12.25 | Y6: =+W6-X6 -> 84.75 | Z6: =+Y6+'2021 day 2'!Z6 -> 220.875 | AA6: =(W6-70)*0.875 -> 23.625
A7: =+A6+1 -> 5 | B7: John Sullivan | C7: 5 | D7: 5 | E7: 5 | F7: 6 | G7: 4 | H7: 5 | I7: 6 | J7: 6 | K7: 4 | L7: =SUM(C7:K7) -> 46 | M7: 5 | N7: 4 | O7: 6 | P7: 4 | Q7: 4 | R7: 6 | S7: 4 | T7: 5 | U7: 4 | V7: =SUM(M7:U7) -> 42 | W7: =+L7+V7 -> 88 | X7: 18.375 | Y7: =+W7-X7 -> 69.625 | Z7: =+Y7+'2021 day 2'!Z7 -> 215.375 | AA7: =(W7-70)*0.875 -> 15.75
A8: =+A7+1 -> 6 | B8: Ralph | C8: 6 | D8: 5 | E8: 5 | F8: 6 | G8: 4 | H8: 6 | I8: 4 | J8: 6 | K8: 4 | L8: =SUM(C8:K8) -> 46 | M8: 6 | N8: 5 | O8: 6 | P8: 6 | Q8: 5 | R8: 3 | S8: 5 | T8: 5 | U8: 6 | V8: =SUM(M8:U8) -> 47 | W8: =+L8+V8 -> 93 | X8: 18.375 | Y8: =+W8-X8 -> 74.625 | Z8: =+Y8+'2021 day 2'!Z8 -> 212.75 | AA8: =(W8-70)*0.875 -> 20.125
A9: =+A8+1 -> 7 | B9: Leo | C9: 6 | D9: 7 | E9: 5 | F9: 10 | G9: 5 | H9: 6 | I9: 6 | J9: 7 | K9: 4 | L9: =SUM(C9:K9) -> 56 | M9: 6 | N9: 9 | O9: 6 | P9: 10 | Q9: 3 | R9: 4 | S9: 7 | T9: 7 | U9: 6 | V9: =SUM(M9:U9) -> 58 | W9: =+L9+V9 -> 114 | X9: 49.875 | Y9: =+W9-X9 -> 64.125 | Z9: =+Y9+'2021 day 2'!Z9 -> 212.375 | AA9: =(W9-70)*0.875 -> 38.5
A10: =+A9+1 -> 8 | B10: Matt Lawrence | L10: =SUM(C10:K10) -> 0 | V10: =SUM(M10:U10) -> 0 | W10: =+L10+V10 -> 0 | X10: 18.375 | Y10: =+W10-X10 -> -18.375 | Z10: =+Y10+'2021 day 2'!Z10 -> 130.375 | AA10: =(W10-70)*0.875 -> -61.25
A11: =+A10+1 -> 9 | B11: Jerry Flynn | L11: =SUM(C11:K11) -> 0 | V11: =SUM(M11:U11) -> 0 | W11: =+L11+V11 -> 0 | X11: 17.5 | Y11: =+W11-X11 -> -17.5 | Z11: =+Y11+'2021 day 2'!Z11 -> 129.125 | AA11: =(W11-70)*0.875 -> -61.25
A12: =+A11+1 -> 10 | B12: Mike Flynn | C12: 5 | D12: 4 | E12: 5 | F12: 6 | G12: 3 | H12: 4 | I12: 6 | J12: 5 | K12: 5 | L12: =SUM(C12:K12) -> 43 | M12: 5 | N12: 4 | O12: 5 | P12: 7 | Q12: 4 | R12: 4 | S12: 6 | T12: 5 | U12: 6 | V12: =SUM(M12:U12) -> 46 | W12: =+L12+V12 -> 89 | X12: 5.25 | Y12: =+W12-X12 -> 83.75 | Z12: =+Y12+'2021 day 2'!Z12 -> 217.625 | AA12: =(W12-70)*0.875 -> 16.625
A13: =+A12+1 -> 11 | B13: Sean Flynn | L13: =SUM(C13:K13) -> 0 | V13: =SUM(M13:U13) -> 0 | W13: =+L13+V13 -> 0 | X13: 9.625 | Y13: =+W13-X13 -> -9.625 | Z13: =+Y13+'2021 day 2'!Z13 -> 138.25 | AA13: =(W13-70)*0.875 -> -61.25
A14: =+A13+1 -> 12 | B14: Kevin Fitzgerald | C14: 6 | D14: 5 | E14: 6 | F14: 6 | G14: 4 | H14: 5 | I14: 6 | J14: 4 | K14: 5 | L14: =SUM(C14:K14) -> 47 | M14: 5 | N14: 4 | O14: 5 | P14: 8 | Q14: 4 | R14: 9 | S14: 5 | T14: 6 | U14: 7 | V14: =SUM(M14:U14) -> 53 | W14: =+L14+V14 -> 100 | X14: 17.5 | Y14: =+W14-X14 -> 82.5 | Z14: =+Y14+'2021 day 2'!Z14 -> 220.75 | AA14: =(W14-70)*0.875 -> 26.25
A15: =+A14+1 -> 13 | B15: Richard McGovern | C15: 5 | D15: 5 | E15: 5 | F15: 7 | G15: 4 | H15: 3 | I15: 6 | J15: 6 | K15: 6 | L15: =SUM(C15:K15) -> 47 | M15: 4 | N15: 7 | O15: 6 | P15: 11 | Q15: 4 | R15: 3 | S15: 6 | T15: 5 | U15: 6 | V15: =SUM(M15:U15) -> 52 | W15: =+L15+V15 -> 99 | X15: 25.375 | Y15: =+W15-X15 -> 73.625 | Z15: =+Y15+'2021 day 2'!Z15 -> 218.125 | AA15: =(W15-70)*0.875 -> 25.375
A16: =+A15+1 -> 14 | B16: Mike Fitzgerald | C16: 4 | D16: 5 | E16: 4 | F16: 8 | G16: 5 | H16: 3 | I16: 5 | J16: 4 | K16: 4 | L16: =SUM(C16:K16) -> 42 | M16: 4 | N16: 4 | O16: 5 | P16: 5 | Q16: 3 | R16: 4 | S16: 5 | T16: 6 | U16: 4 | V16: =SUM(M16:U16) -> 40 | W16: =+L16+V16 -> 82 | X16: 8.75 | Y16: =+W16-X16 -> 73.25 | Z16: =+Y16+'2021 day 2'!Z16 -> 210.875 | AA16: =(W16-70)*0.875 -> 10.5
A17: =+A16+1 -> 15 | B17: Matt Brauer | L17: =SUM(C17:K17) -> 0 | V17: =SUM(M17:U17) -> 0 | W17: =+L17+V17 -> 0 | X17: 9.625 | Y17: =+W17-X17 -> -9.625 | Z17: =+Y17+'2021 day 2'!Z17 -> 142.25 | AA17: =(W17-70)*0.875 -> -61.25
A18: =+A17+1 -> 16 | B18: Blake Dougan | L18: =SUM(C18:K18) -> 0 | V18: =SUM(M18:U18) -> 0 | W18: =+L18+V18 -> 0 | X18: 28 | Y18: =+W18-X18 -> -28 | Z18: =+Y18+'2021 day 2'!Z18 -> 148 | AA18: =(W18-70)*0.875 -> -61.25
A19: =+A18+1 -> 17 | B19: Mike Dougan | L19: =SUM(C19:K19) -> 0 | V19: =SUM(M19:U19) -> 0 | W19: =+L19+V19 -> 0 | X19: 23.625 | Y19: =+W19-X19 -> -23.625 | Z19: =+Y19+'2021 day 2'!Z19 -> 146.75 | AA19: =(W19-70)*0.875 -> -61.25
A20: =+A19+1 -> 18 | B20: TJ Williams | L20: =SUM(C20:K20) -> 0 | V20: =SUM(M20:U20) -> 0 | W20: =+L20+V20 -> 0 | X20: 25.375 | Y20: =+W20-X20 -> -25.375 | Z20: =+Y20+'2021 day 2'!Z20 -> 147.25 | AA20: =(W20-70)*0.875 -> -61.25
A21: =+A20+1 -> 19 | B21: Brian McGovern | L21: =SUM(C21:K21) -> 0 | V21: =SUM(M21:U21) -> 0 | W21: =+L21+V21 -> 0 | X21: -61.25 | Y21: =+W21-X21 -> 61.25 | Z21: =+Y21+'2021 day 2'!Z21 -> 118.5 | AA21: =(W21-70)*0.875 -> -61.25
A22: =+A21+1 -> 20 | B22: Dave Keyser | L22: =SUM(C22:K22) -> 0 | V22: =SUM(M22:U22) -> 0 | W22: =+L22+V22 -> 0 | X22: 31.5 | Y22: =+W22-X22 -> -31.5 | Z22: =+Y22+'2021 day 2'!Z22 -> 124.5 | AA22: =(W22-70)*0.875 -> -61.25
A23: =+A22+1 -> 21 | B23: Jack Sullivan | C23: 4 | D23: 5 | E23: 5 | F23: 7 | G23: 3 | H23: 4 | I23: 7 | J23: 6 | K23: 5 | L23: =SUM(C23:K23) -> 46 | M23: 6 | N23: 4 | O23: 7 | P23: 7 | Q23: 4 | R23: 3 | S23: 6 | T23: 7 | U23: 5 | V23: =SUM(M23:U23) -> 49 | W23: =+L23+V23 -> 95 | X23: 26.25 | Y23: =+W23-X23 -> 68.75 | Z23: =+Y23+'2021 day 2'!Z23 -> 212.625 | AA23: =(W23-70)*0.875 -> 21.875
A24: =+A23+1 -> 22 | B24: Chris Flynn | C24: 5 | D24: 4 | E24: 5 | F24: 7 | G24: 4 | H24: 4 | I24: 7 | J24: 5 | K24: 5 | L24: =SUM(C24:K24) -> 46 | M24: 4 | N24: 5 | O24: 5 | P24: 6 | Q24: 4 | R24: 4 | S24: 6 | T24: 5 | U24: 5 | V24: =SUM(M24:U24) -> 44 | W24: =+L24+V24 -> 90 | X24: 19.25 | Y24: =+W24-X24 -> 70.75 | Z24: =+Y24+'2021 day 2'!Z24 -> 211.875 | AA24: =(W24-70)*0.875 -> 17.5
B25: HDCP | C25: 11 | D25: 17 | E25: 15 | F25: 7 | G25: 3 | H25: 9 | I25: 1 | J25: 13 | K25: 5 | M25: 12 | N25: 18 | O25: 16 | P25: 8 | Q25: 4 | R25: 10 | S25: 2 | T25: 14 | U25: 6
B27: Net of HDCP
A28: 1 | B28: =+B3 -> Colin Sullivan | C28: =+C3-2 -> 3 | D28: =+D3-1 -> 3 | E28: =+E3-1 -> 4 | F28: =+F3-2 -> 4 | G28: =+G3-2 -> 2 | H28: =+H3-2 -> 2 | I28: =+I3-2 -> 5 | J28: =+J3-1 -> 4 | K28: =+K3-2 -> 3 | L28: =SUM(C28:K28) -> 30 | M28: =+M3-2 -> 4 | N28: =+N3-1 -> 5 | O28: =+O3-1 -> 6 | P28: =+P3-2 -> 3 | Q28: =+Q3-2 -> 1 | R28: =+R3-2 -> 2 | S28: =+S3-2 -> 4 | T28: =+T3-1 -> 4 | U28: =+U3-2 -> 2 | V28: =SUM(M28:U28) -> 31 | W28: =+V28+L28 -> 61 | X28: =(0.5*6)-(0.5*6) -> 0 | Y28: =(0.5*4)-(0.5*10) -> -3 | Z28: =(1*5)-(1*9) -> -4 | AA28: =SUM(X28:Z28) -> -7 | AB28: -2.6 | AC28: =SUM(AA28:AB28) -> -9.6
A29: =+A28+1 -> 2 | B29: =+B4 -> Bernie Sullivan | C29: =+C4-1 -> 3 | D29: =+D4 -> 4 | E29: =+E4-1 -> 5 | F29: =+F4-1 -> 6 | G29: =+G4-1 -> 2 | H29: =+H4-1 -> 3 | I29: =+I4-1 -> 4 | J29: =+J4-1 -> 4 | K29: =+K4-1 -> 4 | L29: =SUM(C29:K29) -> 35 | M29: =+M4-1 -> 3 | N29: =+N4 -> 5 | O29: =+O4 -> 6 | P29: =+P4-1 -> 6 | Q29: =+Q4-1 -> 2 | R29: =+R4-1 -> 3 | S29: =+S4-1 -> 5 | T29: =+T4-1 -> 4 | U29: =+U4-1 -> 4 | V29: =SUM(M29:U29) -> 38 | W29: =+V29+L29 -> 73 | X29: =(0.5*6)-(0.5*6) -> 0 | Y29: =(0.5*4)-(0.5*10) -> -3 | Z29: =(1*5)-(1*9) -> -4 | AA29: =SUM(X29:Z29) -> -7 | AB29: -4.7 | AC29: =SUM(AA29:AB29) -> -11.7
A30: =+A29+1 -> 3 | B30: =+B5 -> Joe McCardel | C30: =+C5-2 -> 2 | D30: =+D5-1 -> 6 | E30: =+E5-1 -> 5 | F30: =+F5-2 -> 4 | G30: =+G5-2 -> 7 | H30: =+H5-2 -> 2 | I30: =+I5-2 -> 5 | J30: =+J5-2 -> 3 | K30: =+K5-2 -> 2 | L30: =SUM(C30:K30) -> 36 | M30: =+M5-2 -> 3 | N30: =+N5-1 -> 6 | O30: =+O5-1 -> 6 | P30: =+P5-2 -> 3 | Q30: =+Q5-2 -> 0 | R30: =+R5-2 -> 1 | S30: =+S5-2 -> 6 | T30: =+T5-1 -> 6 | U30: =+U5-2 -> 3 | V30: =SUM(M30:U30) -> 34 | W30: =+V30+L30 -> 70 | X30: =(0.5*2)-(0.5*12) -> -5 | Y30: =(0.5*13)-(0.5*1) -> 6 | Z30: =(1*8)-(1*7) -> 1 | AA30: =SUM(X30:Z30) -> 2 | AB30: -0.3 | AC30: =SUM(AA30:AB30) -> 1.7
A31: =+A30+1 -> 4 | B31: =+B6 -> Dave Brauer | C31: =+C6-1 -> 4 | D31: =+D6 -> 5 | E31: =+E6-1 -> 5 | F31: =+F6-1 -> 6 | G31: =+G6-1 -> 2 | H31: =+H6-1 -> 3 | I31: =+I6-1 -> 4 | J31: =+J6-1 -> 6 | K31: =+K6-1 -> 6 | L31: =SUM(C31:K31) -> 41 | M31: =+M6-1 -> 4 | N31: =+N6 -> 5 | O31: =+O6-1 -> 4 | P31: =+P6-1 -> 6 | Q31: =+Q6-1 -> 3 | R31: =+R6-1 -> 3 | S31: =+S6-1 -> 5 | T31: =+T6-1 -> 5 | U31: =+U6-1 -> 5 | V31: =SUM(M31:U31) -> 40 | W31: =+V31+L31 -> 81 | X31: =(0.5*6)-(0.5*6) -> 0 | Y31: =(0.5*13)-(0.5*1) -> 6 | Z31: =(1*11)-(1*3) -> 8 | AA31: =SUM(X31:Z31) -> 14 | AB31: 4.9 | AC31: =SUM(AA31:AB31) -> 18.9
A32: =+A31+1 -> 5 | B32: =+B7 -> John Sullivan | C32: =+C7-1 -> 4 | D32: =+D7-1 -> 4 | E32: =+E7-1 -> 4 | F32: =+F7-1 -> 5 | G32: =+G7-2 -> 2 | H32: =+H7-1 -> 4 | I32: =+I7-2 -> 4 | J32: =+J7-1 -> 5 | K32: =+K7-1 -> 3 | L32: =SUM(C32:K32) -> 35 | M32: =+M7-1 -> 4 | N32: =+N7-1 -> 3 | O32: =+O7-1 -> 5 | P32: =+P7-1 -> 3 | Q32: =+Q7-2 -> 2 | R32: =+R7-1 -> 5 | S32: =+S7-2 -> 2 | T32: =+T7-1 -> 4 | U32: =+U7-1 -> 3 | V32: =SUM(M32:U32) -> 31 | W32: =+V32+L32 -> 66 | X32: =(0.5*6)-(0.5*6) -> 0 | Y32: =(0.5*12)-(0.5*3) -> 4.5 | Z32: =(1*10)-(1*5) -> 5 | AA32: =SUM(X32:Z32) -> 9.5 | AB32: 4.9 | AC32: =SUM(AA32:AB32) -> 14.4
A33: =+A32+1 -> 6 | B33: =+B8 -> Ralph | C33: =+C8-1 -> 5 | D33: =+D8 -> 5 | E33: =+E8 -> 5 | F33: =+F8-1 -> 5 | G33: =+G8-1 -> 3 | H33: =+H8-1 -> 5 | I33: =+I8-1 -> 3 | J33: =+J8 -> 6 | K33: =+K8-1 -> 3 | L33: =SUM(C33:K33) -> 40 | M33: =+M8 -> 6 | N33: =+N8 -> 5 | O33: =+O8 -> 6 | P33: =+P8-1 -> 5 | Q33: =+Q8-1 -> 4 | R33: =+R8-1 -> 2 | S33: =+S8-1 -> 4 | T33: =+T8 -> 5 | U33: =+U8-1 -> 5 | V33: =SUM(M33:U33) -> 42 | W33: =+V33+L33 -> 82 | X33: =(0.5*12)-(0.5*3) -> 4.5 | Y33: =15*0.5 -> 7.5 | Z33: 15 | AA33: =SUM(X33:Z33) -> 27 | AB33: 11.8 | AC33: =SUM(AA33:AB33) -> 38.8
A34: =+A33+1 -> 7 | B34: =+B9 -> Leo | C34: =+C9-3 -> 3 | D34: =+D9-3 -> 4 | E34: =+E9-3 -> 2 | F34: =+F9-3 -> 7 | G34: =+G9-4 -> 1 | H34: =+H9-3 -> 3 | I34: =+I9-4 -> 2 | J34: =+J9-3 -> 4 | K34: =+K9-3 -> 1 | L34: =SUM(C34:K34) -> 27 | M34: =+M9-3 -> 3 | N34: =+N9-3 -> 6 | O34: =+O9-3 -> 3 | P34: =+P9-3 -> 7 | Q34: =+Q9-3 -> 0 | R34: =+R9-3 -> 1 | S34: =+S9-4 -> 3 | T34: =+T9-3 -> 4 | U34: =+U9-3 -> 3 | V34: =SUM(M34:U34) -> 30 | W34: =+V34+L34 -> 57 | X34: =15*0.5 -> 7.5 | Y34: =(0.5*3)-(0.5*12) -> -4.5 | Z34: =(1*11)-(1*3) -> 8 | AA34: =SUM(X34:Z34) -> 11 | AB34: -0.3 | AC34: =SUM(AA34:AB34) -> 10.7
A35: =+A34+1 -> 8 | B35: =+B10 -> Matt Lawrence | C35: =+C10-1 -> -1 | D35: =+D10-1 -> -1 | E35: =+E10-1 -> -1 | F35: =+F10-1 -> -1 | G35: =+G10-1 -> -1 | H35: =+H10-1 -> -1 | I35: =+I10-1 -> -1 | J35: =+J10-1 -> -1 | K35: =+K10-1 -> -1 | L35: =SUM(C35:K35) -> -9 | M35: =+M10-1 -> -1 | N35: =+N10-1 -> -1 | O35: =+O10-1 -> -1 | P35: =+P10-1 -> -1 | Q35: =+Q10-1 -> -1 | R35: =+R10-1 -> -1 | S35: =+S10-1 -> -1 | T35: =+T10-1 -> -1 | U35: =+U10-1 -> -1 | V35: =SUM(M35:U35) -> -9 | W35: =+V35+L35 -> -18 | X35: =(0.5*13)-(0.5*2) -> 5.5 | Y35: =(0.5*10)-(0.5*4) -> 3 | Z35: =(1*13)-(1*2) -> 11 | AA35: =SUM(X35:Z35) -> 19.5 | AB35: 7.3 | AC35: =SUM(AA35:AB35) -> 26.8
A36: =+A35+1 -> 9 | B36: =+B11 -> Jerry Flynn | C36: =+C11-1 -> -1 | D36: =+D11-1 -> -1 | E36: =+E11-1 -> -1 | F36: =+F11-1 -> -1 | G36: =+G11-1 -> -1 | H36: =+H11-1 -> -1 | I36: =+I11-1 -> -1 | J36: =+J11-1 -> -1 | K36: =+K11-1 -> -1 | L36: =SUM(C36:K36) -> -9 | M36: =+M11-1 -> -1 | N36: =+N11 -> 0 | O36: =+O11-1 -> -1 | P36: =+P11-1 -> -1 | Q36: =+Q11-1 -> -1 | R36: =+R11-1 -> -1 | S36: =+S11-1 -> -1 | T36: =+T11-1 -> -1 | U36: =+U11-1 -> -1 | V36: =SUM(M36:U36) -> -8 | W36: =+V36+L36 -> -17 | X36: =(0.5*4)-(0.5*11) -> -3.5 | Y36: =(0.5*1)-(0.5*13) -> -6 | Z36: =(1*1)-(1*14) -> -13 | AA36: =SUM(X36:Z36) -> -22.5 | AB36: -11.1 | AC36: =SUM(AA36:AB36) -> -33.6
A37: =+A36+1 -> 10 | B37: =+B12 -> Mike Flynn | C37: =+C12 -> 5 | D37: =+D12 -> 4 | E37: =+E12 -> 5 | F37: =+F12-1 -> 5 | G37: =+G12-1 -> 2 | H37: =+H12 -> 4 | I37: =+I12-1 -> 5 | J37: =+J12 -> 5 | K37: =+K12-1 -> 4 | L37: =SUM(C37:K37) -> 39 | M37: =+M12 -> 5 | N37: =+N12 -> 4 | O37: =+O12 -> 5 | P37: =+P12 -> 7 | Q37: =+Q12-1 -> 3 | R37: =+R12 -> 4 | S37: =+S12-1 -> 5 | T37: =+T12 -> 5 | U37: =+U12-1 -> 5 | V37: =SUM(M37:U37) -> 43 | W37: =+V37+L37 -> 82 | X37: =(0.5*11)-(0.5*4) -> 3.5 | Y37: =(0.5*6)-(0.5*9) -> -1.5 | Z37: =(1*9)-(1*6) -> 3 | AA37: =SUM(X37:Z37) -> 5 | AB37: -1.9 | AC37: =SUM(AA37:AB37) -> 3.1
A38: =+A37+1 -> 11 | B38: =+B13 -> Sean Flynn | C38: =+C13-1 -> -1 | D38: =+D13 -> 0 | E38: =+E13 -> 0 | F38: =+F13-1 -> -1 | G38: =+G13-1 -> -1 | H38: =+H13-1 -> -1 | I38: =+I13-1 -> -1 | J38: =+J13-1 -> -1 | K38: =+K13-1 -> -1 | L38: =SUM(C38:K38) -> -7 | M38: =+M13-1 -> -1 | N38: =+N13 -> 0 | O38: =+O13 -> 0 | P38: =+P13-1 -> -1 | Q38: =+Q13-1 -> -1 | R38: =+R13-1 -> -1 | S38: =+S13-1 -> -1 | T38: =+T13 -> 0 | U38: =+U13-1 -> -1 | V38: =SUM(M38:U38) -> -6 | W38: =+V38+L38 -> -13 | X38: -7.5 | Y38: -7.5 | Z38: -15 | AA38: =SUM(X38:Z38) -> -30 | AB38: -12 | AC38: =SUM(AA38:AB38) -> -42
A39: =+A38+1 -> 12 | B39: =+B14 -> Kevin Fitzgerald | C39: =+C14-1 -> 5 | D39: =+D14-1 -> 4 | E39: =+E14-1 -> 5 | F39: =+F14-2 -> 4 | G39: =+G14-2 -> 2 | H39: =+H14-1 -> 4 | I39: =+I14-2 -> 4 | J39: =+J14-1 -> 3 | K39: =+K14-2 -> 3 | L39: =SUM(C39:K39) -> 34 | M39: =+M14-1 -> 4 | N39: =+N14-1 -> 3 | O39: =+O14-1 -> 4 | P39: =+P14-1 -> 7 | Q39: =+Q14-2 -> 2 | R39: =+R14-1 -> 8 | S39: =+S14-2 -> 3 | T39: =+T14-1 -> 5 | U39: =+U14-2 -> 5 | V39: =SUM(M39:U39) -> 41 | W39: =+V39+L39 -> 75 | X39: =14*0.5-0.5 -> 6.5 | Y39: =(0.5*10)-(0.5*4) -> 3 | Z39: =(1*14)-(1*1) -> 13 | AA39: =SUM(X39:Z39) -> 22.5 | AB39: 12 | AC39: =SUM(AA39:AB39) -> 34.5
A40: =+A39+1 -> 13 | B40: =+B15 -> Richard McGovern | C40: =+C15-1 -> 4 | D40: =+D15-1 -> 4 | E40: =+E15-1 -> 4 | F40: =+F15-2 -> 5 | G40: =+G15-2 -> 2 | H40: =+H15-1 -> 2 | I40: =+I15-2 -> 4 | J40: =+J15-1 -> 5 | K40: =+K15-2 -> 4 | L40: =SUM(C40:K40) -> 34 | M40: =+M15-1 -> 3 | N40: =+N15-1 -> 6 | O40: =+O15-1 -> 5 | P40: =+P15-1 -> 10 | Q40: =+Q15-2 -> 2 | R40: =+R15-1 -> 2 | S40: =+S15-2 -> 4 | T40: =+T15-1 -> 4 | U40: =+U15-2 -> 4 | V40: =SUM(M40:U40) -> 40 | W40: =+V40+L40 -> 74 | X40: =(0.5*10)-(0.5*5) -> 2.5 | Y40: =(0.5*1)-(0.5*13) -> -6 | Z40: =(1*4)-(1*11) -> -7 | AA40: =SUM(X40:Z40) -> -10.5 | AB40: -1.5 | AC40: =SUM(AA40:AB40) -> -12
A41: =+A40+1 -> 14 | B41: =+B16 -> Mike Fitzgerald | C41: =+C16-1 -> 3 | D41: =+D16 -> 5 | E41: =+E16 -> 4 | F41: =+F16-1 -> 7 | G41: =+G16-1 -> 4 | H41: =+H16-1 -> 2 | I41: =+I16-1 -> 4 | J41: =+J16 -> 4 | K41: =+K16-1 -> 3 | L41: =SUM(C41:K41) -> 36 | M41: =+M16 -> 4 | N41: =+N16 -> 4 | O41: =+O16 -> 5 | P41: =+P16-1 -> 4 | Q41: =+Q16-1 -> 2 | R41: =+R16-1 -> 3 | S41: =+S16-1 -> 4 | T41: =+T16 -> 6 | U41: =+U16-1 -> 3 | V41: =SUM(M41:U41) -> 35 | W41: =+V41+L41 -> 71 | X41: =(0.5*2)-(0.5*12) -> -5 | Y41: =(0.5*7)-(0.5*7) -> 0 | Z41: =(1*3)-(1*12) -> -9 | AA41: =SUM(X41:Z41) -> -14 | AB41: -2.2 | AC41: =SUM(AA41:AB41) -> -16.2
...

Sheet Sheet2

Sheet Sheet1
C1: Name | D1: Front | E1: Back | F1: total | H1: Front | L1: Front | M1: Back | N1: Total | AC1: Wins | AD1: Losses | AE1: Owed | AF1: Multipler | AG1: Given
B2: 1 | C2: Ralph | D2: 27 | E2: 31 | F2: =SUM(D2:E2) -> 58 | G2: =IF(D2<D2,"","") | H2: 21 | K2: Bernie Sullivan | L2: 21 | M2: 5 | AC2: =IF($D$2<D2,1,0) -> 0 | AD2: =21-AC2 -> 21 | AE2: =-AD2*0.5 -> -10.5 | AF2: 0.5 | AG2: =+AC2*AF2 -> 0
B3: 2 | C3: Bernie Sullivan | D3: 26 | E3: 37 | F3: =SUM(D3:E3) -> 63 | G3: =IF(D3<D4,"WIN","") -> WIN | H3: =20-1 -> 19 | K3: Ralph | L3: 19 | M3: 21 | AC3: =IF($D$2<D3,1,0) -> 0 | AD3: =21-AC3 -> 21 | AE3: =-AD3*0.5 -> -10.5 | AF3: 0.5 | AG3: =+AC3*AF3 -> 0
B4: 3 | C4: Mike Flynn | D4: 31 | E4: 34 | F4: =SUM(D4:E4) -> 65 | G4: =IF(D4<D5,"WIN","TIE") -> WIN | H4: =19-2 -> 17 | K4: Mike Flynn | L4: 16 | M4: 16 | AC4: =IF($D$2<D4,1,0) -> 1 | AD4: 2 | AE4: =-AD4*0.5 -> -1 | AF4: 0.5 | AG4: =+AC4*AF4 -> 0.5
B5: 4 | C5: Colin Sullivan | D5: 36 | E5: 32 | F5: =SUM(D5:E5) -> 68 | G5: =IF(D5<D6,"WIN","TIE") -> TIE | H5: =+H4 -> 17 | K5: Mike Fitzgerald | L5: 16 | M5: 5 | AC5: =IF($D$2<D5,1,0) -> 1 | AD5: 2 | AE5: =-AD5*0.5 -> -1 | AF5: 0.5 | AG5: =+AC5*AF5 -> 0.5
B6: 5 | C6: Dave Brauer | D6: 34 | E6: 34 | F6: =SUM(D6:E6) -> 68 | G6: =IF(D6<D7,"WIN","TIE") -> TIE | H6: =16-4 -> 12 | K6: Kevin Fitzgerald | L6: 13 | M6: -11 | AC6: =IF($D$2<D6,1,0) -> 1 | AD6: =21-AC6 -> 20 | AE6: =-AD6*0.5 -> -10 | AF6: 0.5 | AG6: =+AC6*AF6 -> 0.5
B7: 6 | C7: Mike Fitzgerald | D7: 31 | E7: 37 | F7: =SUM(D7:E7) -> 68 | G7: =IF(D7<D8,"WIN","TIE") -> WIN | H7: =+H6 -> 12 | K7: Dave Brauer | L7: 10 | M7: 16 | AC7: =IF($D$2<D7,1,0) -> 1 | AD7: =21-AC7 -> 20 | AE7: =-AD7*0.5 -> -10 | AF7: 0.5 | AG7: =+AC7*AF7 -> 0.5
B8: 7 | C8: Richard McGovern | D8: 35 | E8: 35 | F8: =SUM(D8:E8) -> 70 | G8: =IF(D8<D9,"WIN","TIE") -> WIN | H8: =11-6 -> 5 | K8: Joe McCardel | L8: 10 | M8: -11 | AC8: =IF($D$2<D8,1,0) -> 1 | AD8: =21-AC8 -> 20 | AE8: =-AD8*0.5 -> -10 | AF8: 0.5 | AG8: =+AC8*AF8 -> 0.5
B9: 8 | C9: Chris Flynn | D9: 36 | E9: 35 | F9: =SUM(D9:E9) -> 71 | G9: =IF(D9<D10,"WIN","TIE") -> TIE | H9: =+H8 -> 5 | K9: Richard McGovern | L9: 7 | M9: 5 | AC9: =IF($D$2<D9,1,0) -> 1 | AD9: =21-AC9 -> 20 | AE9: =-AD9*0.5 -> -10 | AF9: 0.5 | AG9: =+AC9*AF9 -> 0.5
B10: 9 | C10: Jerry Flynn | D10: 36 | E10: 37 | F10: =SUM(D10:E10) -> 73 | G10: =IF(D10<D11,"WIN","TIE") -> WIN | H10: =+H9 -> 5 | K10: Colin Sullivan | L10: 1 | M10: 19 | AC10: =IF($D$2<D10,1,0) -> 1 | AD10: =21-AC10 -> 20 | AE10: =-AD10*0.5 -> -10 | AF10: 0.5 | AG10: =+AC10*AF10 -> 0.5
B11: 10 | C11: Brian McGovern | D11: 37 | E11: 37 | F11: =SUM(D11:E11) -> 74 | G11: =IF(D11<D12,"WIN","TIE") -> TIE | H11: =+H10 -> 5 | K11: Chris Flynn | L11: 1 | M11: 12 | AC11: =IF($D$2<D11,1,0) -> 1 | AD11: =21-AC11 -> 20 | AE11: =-AD11*0.5 -> -10 | AF11: 0.5 | AG11: =+AC11*AF11 -> 0.5
B12: 11 | C12: Kevin Fitzgerald | D12: 33 | E12: 41 | F12: =SUM(D12:E12) -> 74 | G12: =IF(D12<D13,"WIN","TIE") -> WIN | H12: =+H11 -> 5 | K12: Jerry Flynn | L12: 1 | M12: 5 | AC12: =IF($D$2<D12,1,0) -> 1 | AD12: =21-AC12 -> 20 | AE12: =-AD12*0.5 -> -10 | AF12: 0.5 | AG12: =+AC12*AF12 -> 0.5
B13: 12 | C13: Joe McCardel | D13: 34 | E13: 41 | F13: =SUM(D13:E13) -> 75 | G13: =IF(D13<D14,"WIN","TIE") -> WIN | H13: =9-11 -> -2 | K13: John Sullivan | L13: 1 | M13: -11 | AC13: =IF($D$2<D13,1,0) -> 1 | AD13: =21-AC13 -> 20 | AE13: =-AD13*0.5 -> -10 | AF13: 0.5 | AG13: =+AC13*AF13 -> 0.5
B14: 13 | C14: Matt Brauer | D14: 38 | E14: 39 | F14: =SUM(D14:E14) -> 77 | G14: =IF(D14<D15,"WIN","TIE") -> TIE | H14: =+H13 -> -2 | K14: Matt Lawrence | L14: 1 | M14: -11 | AC14: =IF($D$2<D14,1,0) -> 1 | AD14: =21-AC14 -> 20 | AE14: =-AD14*0.5 -> -10 | AF14: 0.5 | AG14: =+AC14*AF14 -> 0.5
B15: 14 | C15: John Sullivan | D15: 36 | E15: 41 | F15: =SUM(D15:E15) -> 77 | G15: =IF(D15<D16,"WIN","TIE") -> TIE | H15: =8-13 -> -5 | K15: Brian McGovern | L15: -5 | M15: 5 | AC15: =IF($D$2<D15,1,0) -> 1 | AD15: =21-AC15 -> 20 | AE15: =-AD15*0.5 -> -10 | AF15: 0.5 | AG15: =+AC15*AF15 -> 0.5
B16: 15 | C16: Matt Lawrence | D16: 36 | E16: 41 | F16: =SUM(D16:E16) -> 77 | G16: =IF(D16<D17,"WIN","TIE") -> WIN | H16: =3-14 -> -11 | K16: Matt Brauer | L16: -8 | M16: -2 | AC16: =IF($D$2<D16,1,0) -> 1 | AD16: =21-AC16 -> 20 | AE16: =-AD16*0.5 -> -10 | AF16: 0.5 | AG16: =+AC16*AF16 -> 0.5
B17: 16 | C17: Leo | D17: 41 | E17: 37 | F17: =SUM(D17:E17) -> 78 | G17: =IF(D17<D18,"WIN","TIE") -> TIE | H17: =+H16 -> -11 | K17: Jack Sullivan | L17: -8 | M17: -5 | AC17: =IF($D$2<D17,1,0) -> 1 | AD17: =21-AC17 -> 20 | AE17: =-AD17*0.5 -> -10 | AF17: 0.5 | AG17: =+AC17*AF17 -> 0.5
B18: 17 | C18: Dave Keyser | D18: 39 | E18: 39 | F18: =SUM(D18:E18) -> 78 | G18: =IF(D18<D19,"WIN","TIE") -> TIE | H18: =+H17 -> -11 | K18: Dave Keyser | L18: -12 | M18: -2 | AC18: =IF($D$2<D18,1,0) -> 1 | AD18: =21-AC18 -> 20 | AE18: =-AD18*0.5 -> -10 | AF18: 0.5 | AG18: =+AC18*AF18 -> 0.5
B19: 18 | C19: Jack Sullivan | D19: 38 | E19: 40 | F19: =SUM(D19:E19) -> 78 | G19: =IF(D19<D20,"WIN","TIE") -> WIN | H19: =+H18 -> -11 | K19: Sean Flynn | L19: -12 | M19: -11 | AC19: =IF($D$2<D19,1,0) -> 1 | AD19: =21-AC19 -> 20 | AE19: =-AD19*0.5 -> -10 | AF19: 0.5 | AG19: =+AC19*AF19 -> 0.5
B20: 19 | C20: Sean Flynn | D20: 39 | E20: 41 | F20: =SUM(D20:E20) -> 80 | G20: =IF(D20<D21,"WIN","TIE") -> WIN | H20: =+H19 -> -11 | K20: Leo | L20: -15 | M20: 5 | AC20: =IF($D$2<D20,1,0) -> 1 | AD20: =21-AC20 -> 20 | AE20: =-AD20*0.5 -> -10 | AF20: 0.5 | AG20: =+AC20*AF20 -> 0.5
B21: 20 | C21: Mike Dougan | D21: 47 | E21: 50 | F21: =SUM(D21:E21) -> 97 | G21: =IF(D21<D22,"WIN","TIE") -> WIN | H21: =2-19 -> -17 | K21: Mike Dougan | L21: -17 | M21: -19 | AC21: =IF($D$2<D21,1,0) -> 1 | AD21: =21-AC21 -> 20 | AE21: =-AD21*0.5 -> -10 | AF21: 0.5 | AG21: =+AC21*AF21 -> 0.5
B22: 21 | C22: TJ Williams | D22: 53 | E22: 46 | F22: =SUM(D22:E22) -> 99 | G22: =IF(D22<D23,"WIN","TIE") -> TIE | H22: =1-20 -> -19 | K22: Blake Dougan | L22: -19 | M22: -21 | AC22: =IF($D$2<D22,1,0) -> 1 | AD22: =21-AC22 -> 20 | AE22: =-AD22*0.5 -> -10 | AF22: 0.5 | AG22: =+AC22*AF22 -> 0.5
B23: 22 | C23: Blake Dougan | D23: 51 | E23: 51 | F23: =SUM(D23:E23) -> 102 | G23: =IF(D23<D24,"WIN","TIE") -> TIE | H23: -21 | K23: TJ Williams | L23: -21 | M23: -17 | AC23: =IF($D$2<D23,1,0) -> 1 | AD23: =21-AC23 -> 20 | AE23: =-AD23*0.5 -> -10 | AF23: 0.5 | AG23: 0
H24: =SUM(H2:H23) -> 2 | L24: 0 | M24: 0 | AC24: =SUM(AC2:AC23) -> 20 | AD24: =SUM(AD2:AD23) -> 406 | AE24: =SUM(AE2:AE23) -> -203 | AG24: =SUM(AG2:AG23) -> 9.5

Sheet day 2
X1: Day 2 | Z1: Day 2 | AA1: Day 3
B2: Name | C2: 1 | D2: 2 | E2: 3 | F2: 4 | G2: 5 | H2: 6 | I2: 7 | J2: 8 | K2: 9 | L2: Front | M2: 10 | N2: 11 | O2: 12 | P2: 13 | Q2: 14 | R2: 15 | S2: 16 | T2: 17 | U2: 18 | V2: Back | W2: Total | X2: HDCP | Z2: Net | AA2: HDCP
B3: Dave Kizer | C3: 5 | D3: 5 | E3: 4 | F3: 7 | G3: 4 | H3: 7 | I3: 6 | J3: 6 | K3: 6 | L3: =SUM(C3:K3) -> 50 | M3: 6 | N3: 5 | O3: 6 | P3: 6 | Q3: 5 | R3: 4 | S3: 6 | T3: 4 | U3: 5 | V3: =SUM(M3:U3) -> 47 | W3: =+L3+V3 -> 97 | X3: =+'day 1'!AA3 -> 29.75 | Y3: =(+W3-70)*0.87 -> 23.49 | Z3: =+W3-Y3 -> 73.51 | AA3: =(W3-70)*0.875 -> 23.625 | AB3: =+Z3+'day 1'!Z3 -> 141.51
B4: Bernie Sullivan | C4: 5 | D4: 4 | E4: 5 | F4: 6 | G4: 5 | H4: 4 | I4: 5 | J4: 6 | K4: 3 | L4: =SUM(C4:K4) -> 43 | M4: 5 | N4: 4 | O4: 5 | P4: 5 | Q4: 3 | R4: 5 | S4: 7 | T4: 4 | U4: 4 | V4: =SUM(M4:U4) -> 42 | W4: =+L4+V4 -> 85 | X4: =+'day 1'!AA4 -> 14 | Y4: =(+W4-70)*0.875 -> 13.125 | Z4: =+W4-X4 -> 71 | AA4: =(W4-70)*0.875 -> 13.125 | AB4: =+Z4+'day 1'!Z4 -> 134.25
B5: Joe McCardel | C5: 7 | D5: 7 | E5: 7 | F5: 7 | G5: 6 | H5: 7 | I5: 6 | J5: 7 | K5: 5 | L5: =SUM(C5:K5) -> 59 | M5: 7 | N5: 5 | O5: 6 | P5: 8 | Q5: 4 | R5: 5 | S5: 5 | T5: 5 | U5: 5 | V5: =SUM(M5:U5) -> 50 | W5: =+L5+V5 -> 109 | X5: =+'day 1'!AA5 -> 30.625 | Y5: =(+W5-70)*0.875 -> 34.125 | Z5: =+W5-X5 -> 78.375 | AA5: =(W5-70)*0.875 -> 34.125 | AB5: =+Z5+'day 1'!Z5 -> 153.625
B6: Dave Brauer | C6: 5 | D6: 5 | E6: 5 | F6: 7 | G6: 5 | H6: 6 | I6: 5 | J6: 6 | K6: 6 | L6: =SUM(C6:K6) -> 50 | M6: 5 | N6: 6 | O6: 6 | P6: 6 | Q6: 5 | R6: 4 | S6: 6 | T6: 4 | U6: 5 | V6: =SUM(M6:U6) -> 47 | W6: =+L6+V6 -> 97 | X6: =+'day 1'!AA6 -> 15.75 | Y6: =(+W6-70)*0.875 -> 23.625 | Z6: =+W6-X6 -> 81.25 | AA6: =(W6-70)*0.875 -> 23.625 | AB6: =+Z6+'day 1'!Z6 -> 149.125
B7: John Sullivan | C7: 7 | D7: 4 | E7: 5 | F7: 6 | G7: 4 | H7: 4 | I7: 7 | J7: 5 | K7: 4 | L7: =SUM(C7:K7) -> 46 | M7: 6 | N7: 5 | O7: 6 | P7: 6 | Q7: 2 | R7: 4 | S7: 5 | T7: 4 | U7: 5 | V7: =SUM(M7:U7) -> 43 | W7: =+L7+V7 -> 89 | X7: =+'day 1'!AA7 -> 21.875 | Y7: =(+W7-70)*0.875 -> 16.625 | Z7: =+W7-X7 -> 67.125 | AA7: =(W7-70)*0.875 -> 16.625 | AB7: =+Z7+'day 1'!Z7 -> 143.75 | AC7: =76+62 -> 138
